2022-09-08 16:16:28 [base_events/ERROR]: Fatal error on SSL transport
protocol: <asyncio.sslproto.SSLProtocol object at 0x7f5c897e0a30>
transport: <_SelectorSocketTransport closing fd=10>
Traceback (most recent call last):
  File "/usr/local/lib/python3.10/asyncio/selector_events.py", line 916, in write
    n = self._sock.send(data)
OSError: [Errno 9] Bad file descriptor

During handling of the above exception, another exception occurred:

Traceback (most recent call last):
  File "/usr/local/lib/python3.10/asyncio/sslproto.py", line 690, in _process_write_backlog
    self._transport.write(chunk)
  File "/usr/local/lib/python3.10/asyncio/selector_events.py", line 922, in write
    self._fatal_error(exc, 'Fatal write error on socket transport')
  File "/usr/local/lib/python3.10/asyncio/selector_events.py", line 717, in _fatal_error
    self._force_close(exc)
  File "/usr/local/lib/python3.10/asyncio/selector_events.py", line 729, in _force_close
    self._loop.call_soon(self._call_connection_lost, exc)
  File "/usr/local/lib/python3.10/asyncio/base_events.py", line 750, in call_soon
    self._check_closed()
  File "/usr/local/lib/python3.10/asyncio/base_events.py", line 515, in _check_closed
    raise RuntimeError('Event loop is closed')
RuntimeError: Event loop is closed
2022-09-08 16:16:28 [base_events/ERROR]: Fatal error on SSL transport
protocol: <asyncio.sslproto.SSLProtocol object at 0x7f5c897e0cd0>
transport: <_SelectorSocketTransport closing fd=9>
Traceback (most recent call last):
  File "/usr/local/lib/python3.10/asyncio/selector_events.py", line 916, in write
    n = self._sock.send(data)
OSError: [Errno 9] Bad file descriptor

During handling of the above exception, another exception occurred:

Traceback (most recent call last):
  File "/usr/local/lib/python3.10/asyncio/sslproto.py", line 690, in _process_write_backlog
    self._transport.write(chunk)
  File "/usr/local/lib/python3.10/asyncio/selector_events.py", line 922, in write
    self._fatal_error(exc, 'Fatal write error on socket transport')
  File "/usr/local/lib/python3.10/asyncio/selector_events.py", line 717, in _fatal_error
    self._force_close(exc)
  File "/usr/local/lib/python3.10/asyncio/selector_events.py", line 729, in _force_close
    self._loop.call_soon(self._call_connection_lost, exc)
  File "/usr/local/lib/python3.10/asyncio/base_events.py", line 750, in call_soon
    self._check_closed()
  File "/usr/local/lib/python3.10/asyncio/base_events.py", line 515, in _check_closed
    raise RuntimeError('Event loop is closed')
RuntimeError: Event loop is closed
2022-09-08 16:16:28 [base_events/ERROR]: Task was destroyed but it is pending!
task: <Task pending name='Task-194' coro=<Throttler.looper() running at /usr/local/lib/python3.10/site-packages/ccxt/async_support/base/throttler.py:36> wait_for=<Future pending cb=[Task.task_wakeup()]>>
2022-09-08 16:16:28 [base_events/ERROR]: Task was destroyed but it is pending!
task: <Task pending name='Task-200' coro=<Throttler.looper() running at /usr/local/lib/python3.10/site-packages/ccxt/async_support/base/throttler.py:36> wait_for=<Future pending cb=[Task.task_wakeup()]>>
2022-09-08 16:16:28 [base_events/ERROR]: Fatal error on SSL transport
protocol: <asyncio.sslproto.SSLProtocol object at 0x7f5c897e0820>
transport: <_SelectorSocketTransport closing fd=8>
Traceback (most recent call last):
  File "/usr/local/lib/python3.10/asyncio/selector_events.py", line 916, in write
    n = self._sock.send(data)
OSError: [Errno 9] Bad file descriptor

During handling of the above exception, another exception occurred:

Traceback (most recent call last):
  File "/usr/local/lib/python3.10/asyncio/sslproto.py", line 690, in _process_write_backlog
    self._transport.write(chunk)
  File "/usr/local/lib/python3.10/asyncio/selector_events.py", line 922, in write
    self._fatal_error(exc, 'Fatal write error on socket transport')
  File "/usr/local/lib/python3.10/asyncio/selector_events.py", line 717, in _fatal_error
    self._force_close(exc)
  File "/usr/local/lib/python3.10/asyncio/selector_events.py", line 729, in _force_close
    self._loop.call_soon(self._call_connection_lost, exc)
  File "/usr/local/lib/python3.10/asyncio/base_events.py", line 750, in call_soon
    self._check_closed()
  File "/usr/local/lib/python3.10/asyncio/base_events.py", line 515, in _check_closed
    raise RuntimeError('Event loop is closed')
RuntimeError: Event loop is closed
2022-09-08 16:16:28 [base_events/ERROR]: Unclosed client session
client_session: <aiohttp.client.ClientSession object at 0x7f5c897b92a0>
2022-09-08 16:16:28 [base_events/ERROR]: Unclosed client session
client_session: <aiohttp.client.ClientSession object at 0x7f5c897b9660>
2022-09-08 16:16:28 [base_events/ERROR]: Unclosed connector
connections: ['[(<aiohttp.client_proto.ResponseHandler object at 0x7f5c897b5a80>, 871.862949773)]']
connector: <aiohttp.connector.TCPConnector object at 0x7f5c898e2020>
2022-09-08 16:16:28 [base_events/ERROR]: Unclosed client session
client_session: <aiohttp.client.ClientSession object at 0x7f5c897b8f40>
2022-09-08 16:16:28 [base_events/ERROR]: Unclosed connector
connections: ['[(<aiohttp.client_proto.ResponseHandler object at 0x7f5c897b58a0>, 872.510677328)]']
connector: <aiohttp.connector.TCPConnector object at 0x7f5c898e15d0>
2022-09-08 16:23:03 [base_events/ERROR]: Task was destroyed but it is pending!
task: <Task pending name='Task-9620' coro=<Throttler.looper() running at /usr/local/lib/python3.10/site-packages/ccxt/async_support/base/throttler.py:36> wait_for=<Future finished result=None>>
2022-09-08 16:23:03 [base_events/ERROR]: Task was destroyed but it is pending!
task: <Task pending name='Task-9617' coro=<Throttler.looper() running at /usr/local/lib/python3.10/site-packages/ccxt/async_support/base/throttler.py:36> wait_for=<Future finished result=None>>
2022-09-08 16:23:03 [base_events/ERROR]: Task was destroyed but it is pending!
task: <Task pending name='Task-9613' coro=<Throttler.looper() running at /usr/local/lib/python3.10/site-packages/ccxt/async_support/base/throttler.py:36> wait_for=<Future finished result=None>>
2022-09-08 16:23:03 [base_events/ERROR]: Task was destroyed but it is pending!
task: <Task pending name='Task-9549' coro=<Throttler.looper() running at /usr/local/lib/python3.10/site-packages/ccxt/async_support/base/throttler.py:36> wait_for=<Future finished result=None>>
2022-09-08 16:23:03 [base_events/ERROR]: Fatal error on SSL transport
protocol: <asyncio.sslproto.SSLProtocol object at 0x7ffba0eea4d0>
transport: <_SelectorSocketTransport closing fd=8>
Traceback (most recent call last):
  File "/usr/local/lib/python3.10/asyncio/selector_events.py", line 916, in write
    n = self._sock.send(data)
OSError: [Errno 9] Bad file descriptor

During handling of the above exception, another exception occurred:

Traceback (most recent call last):
  File "/usr/local/lib/python3.10/asyncio/sslproto.py", line 690, in _process_write_backlog
    self._transport.write(chunk)
  File "/usr/local/lib/python3.10/asyncio/selector_events.py", line 922, in write
    self._fatal_error(exc, 'Fatal write error on socket transport')
  File "/usr/local/lib/python3.10/asyncio/selector_events.py", line 717, in _fatal_error
    self._force_close(exc)
  File "/usr/local/lib/python3.10/asyncio/selector_events.py", line 729, in _force_close
    self._loop.call_soon(self._call_connection_lost, exc)
  File "/usr/local/lib/python3.10/asyncio/base_events.py", line 750, in call_soon
    self._check_closed()
  File "/usr/local/lib/python3.10/asyncio/base_events.py", line 515, in _check_closed
    raise RuntimeError('Event loop is closed')
RuntimeError: Event loop is closed
2022-09-08 16:23:03 [base_events/ERROR]: Fatal error on SSL transport
protocol: <asyncio.sslproto.SSLProtocol object at 0x7ffba0ee9c60>
transport: <_SelectorSocketTransport closing fd=9>
Traceback (most recent call last):
  File "/usr/local/lib/python3.10/asyncio/selector_events.py", line 916, in write
    n = self._sock.send(data)
OSError: [Errno 9] Bad file descriptor

During handling of the above exception, another exception occurred:

Traceback (most recent call last):
  File "/usr/local/lib/python3.10/asyncio/sslproto.py", line 690, in _process_write_backlog
    self._transport.write(chunk)
  File "/usr/local/lib/python3.10/asyncio/selector_events.py", line 922, in write
    self._fatal_error(exc, 'Fatal write error on socket transport')
  File "/usr/local/lib/python3.10/asyncio/selector_events.py", line 717, in _fatal_error
    self._force_close(exc)
  File "/usr/local/lib/python3.10/asyncio/selector_events.py", line 729, in _force_close
    self._loop.call_soon(self._call_connection_lost, exc)
  File "/usr/local/lib/python3.10/asyncio/base_events.py", line 750, in call_soon
    self._check_closed()
  File "/usr/local/lib/python3.10/asyncio/base_events.py", line 515, in _check_closed
    raise RuntimeError('Event loop is closed')
RuntimeError: Event loop is closed
2022-09-08 16:23:03 [base_events/ERROR]: Fatal error on SSL transport
protocol: <asyncio.sslproto.SSLProtocol object at 0x7ffba0ee8640>
transport: <_SelectorSocketTransport closing fd=12>
Traceback (most recent call last):
  File "/usr/local/lib/python3.10/asyncio/selector_events.py", line 916, in write
    n = self._sock.send(data)
OSError: [Errno 9] Bad file descriptor

During handling of the above exception, another exception occurred:

Traceback (most recent call last):
  File "/usr/local/lib/python3.10/asyncio/sslproto.py", line 690, in _process_write_backlog
    self._transport.write(chunk)
  File "/usr/local/lib/python3.10/asyncio/selector_events.py", line 922, in write
    self._fatal_error(exc, 'Fatal write error on socket transport')
  File "/usr/local/lib/python3.10/asyncio/selector_events.py", line 717, in _fatal_error
    self._force_close(exc)
  File "/usr/local/lib/python3.10/asyncio/selector_events.py", line 729, in _force_close
    self._loop.call_soon(self._call_connection_lost, exc)
  File "/usr/local/lib/python3.10/asyncio/base_events.py", line 750, in call_soon
    self._check_closed()
  File "/usr/local/lib/python3.10/asyncio/base_events.py", line 515, in _check_closed
    raise RuntimeError('Event loop is closed')
RuntimeError: Event loop is closed
2022-09-08 16:23:03 [base_events/ERROR]: Fatal error on SSL transport
protocol: <asyncio.sslproto.SSLProtocol object at 0x7ffba305f550>
transport: <_SelectorSocketTransport closing fd=11>
Traceback (most recent call last):
  File "/usr/local/lib/python3.10/asyncio/selector_events.py", line 916, in write
    n = self._sock.send(data)
OSError: [Errno 9] Bad file descriptor

During handling of the above exception, another exception occurred:

Traceback (most recent call last):
  File "/usr/local/lib/python3.10/asyncio/sslproto.py", line 690, in _process_write_backlog
    self._transport.write(chunk)
  File "/usr/local/lib/python3.10/asyncio/selector_events.py", line 922, in write
    self._fatal_error(exc, 'Fatal write error on socket transport')
  File "/usr/local/lib/python3.10/asyncio/selector_events.py", line 717, in _fatal_error
    self._force_close(exc)
  File "/usr/local/lib/python3.10/asyncio/selector_events.py", line 729, in _force_close
    self._loop.call_soon(self._call_connection_lost, exc)
  File "/usr/local/lib/python3.10/asyncio/base_events.py", line 750, in call_soon
    self._check_closed()
  File "/usr/local/lib/python3.10/asyncio/base_events.py", line 515, in _check_closed
    raise RuntimeError('Event loop is closed')
RuntimeError: Event loop is closed
2022-09-08 16:23:03 [base_events/ERROR]: Fatal error on SSL transport
protocol: <asyncio.sslproto.SSLProtocol object at 0x7ffba0ee8e80>
transport: <_SelectorSocketTransport closing fd=13>
Traceback (most recent call last):
  File "/usr/local/lib/python3.10/asyncio/selector_events.py", line 916, in write
    n = self._sock.send(data)
OSError: [Errno 9] Bad file descriptor

During handling of the above exception, another exception occurred:

Traceback (most recent call last):
  File "/usr/local/lib/python3.10/asyncio/sslproto.py", line 690, in _process_write_backlog
    self._transport.write(chunk)
  File "/usr/local/lib/python3.10/asyncio/selector_events.py", line 922, in write
    self._fatal_error(exc, 'Fatal write error on socket transport')
  File "/usr/local/lib/python3.10/asyncio/selector_events.py", line 717, in _fatal_error
    self._force_close(exc)
  File "/usr/local/lib/python3.10/asyncio/selector_events.py", line 729, in _force_close
    self._loop.call_soon(self._call_connection_lost, exc)
  File "/usr/local/lib/python3.10/asyncio/base_events.py", line 750, in call_soon
    self._check_closed()
  File "/usr/local/lib/python3.10/asyncio/base_events.py", line 515, in _check_closed
    raise RuntimeError('Event loop is closed')
RuntimeError: Event loop is closed
2022-09-08 16:23:03 [base_events/ERROR]: Fatal error on SSL transport
protocol: <asyncio.sslproto.SSLProtocol object at 0x7ffba0ee92d0>
transport: <_SelectorSocketTransport closing fd=10>
Traceback (most recent call last):
  File "/usr/local/lib/python3.10/asyncio/selector_events.py", line 916, in write
    n = self._sock.send(data)
OSError: [Errno 9] Bad file descriptor

During handling of the above exception, another exception occurred:

Traceback (most recent call last):
  File "/usr/local/lib/python3.10/asyncio/sslproto.py", line 690, in _process_write_backlog
    self._transport.write(chunk)
  File "/usr/local/lib/python3.10/asyncio/selector_events.py", line 922, in write
    self._fatal_error(exc, 'Fatal write error on socket transport')
  File "/usr/local/lib/python3.10/asyncio/selector_events.py", line 717, in _fatal_error
    self._force_close(exc)
  File "/usr/local/lib/python3.10/asyncio/selector_events.py", line 729, in _force_close
    self._loop.call_soon(self._call_connection_lost, exc)
  File "/usr/local/lib/python3.10/asyncio/base_events.py", line 750, in call_soon
    self._check_closed()
  File "/usr/local/lib/python3.10/asyncio/base_events.py", line 515, in _check_closed
    raise RuntimeError('Event loop is closed')
RuntimeError: Event loop is closed
2022-09-08 16:23:03 [base_events/ERROR]: Fatal error on SSL transport
protocol: <asyncio.sslproto.SSLProtocol object at 0x7ffba107c970>
transport: <_SelectorSocketTransport closing fd=16>
Traceback (most recent call last):
  File "/usr/local/lib/python3.10/asyncio/selector_events.py", line 916, in write
    n = self._sock.send(data)
OSError: [Errno 9] Bad file descriptor

During handling of the above exception, another exception occurred:

Traceback (most recent call last):
  File "/usr/local/lib/python3.10/asyncio/sslproto.py", line 690, in _process_write_backlog
    self._transport.write(chunk)
  File "/usr/local/lib/python3.10/asyncio/selector_events.py", line 922, in write
    self._fatal_error(exc, 'Fatal write error on socket transport')
  File "/usr/local/lib/python3.10/asyncio/selector_events.py", line 717, in _fatal_error
    self._force_close(exc)
  File "/usr/local/lib/python3.10/asyncio/selector_events.py", line 729, in _force_close
    self._loop.call_soon(self._call_connection_lost, exc)
  File "/usr/local/lib/python3.10/asyncio/base_events.py", line 750, in call_soon
    self._check_closed()
  File "/usr/local/lib/python3.10/asyncio/base_events.py", line 515, in _check_closed
    raise RuntimeError('Event loop is closed')
RuntimeError: Event loop is closed
2022-09-08 16:23:03 [base_events/ERROR]: Fatal error on SSL transport
protocol: <asyncio.sslproto.SSLProtocol object at 0x7ffba0eebee0>
transport: <_SelectorSocketTransport closing fd=14>
Traceback (most recent call last):
  File "/usr/local/lib/python3.10/asyncio/selector_events.py", line 916, in write
    n = self._sock.send(data)
OSError: [Errno 9] Bad file descriptor

During handling of the above exception, another exception occurred:

Traceback (most recent call last):
  File "/usr/local/lib/python3.10/asyncio/sslproto.py", line 690, in _process_write_backlog
    self._transport.write(chunk)
  File "/usr/local/lib/python3.10/asyncio/selector_events.py", line 922, in write
    self._fatal_error(exc, 'Fatal write error on socket transport')
  File "/usr/local/lib/python3.10/asyncio/selector_events.py", line 717, in _fatal_error
    self._force_close(exc)
  File "/usr/local/lib/python3.10/asyncio/selector_events.py", line 729, in _force_close
    self._loop.call_soon(self._call_connection_lost, exc)
  File "/usr/local/lib/python3.10/asyncio/base_events.py", line 750, in call_soon
    self._check_closed()
  File "/usr/local/lib/python3.10/asyncio/base_events.py", line 515, in _check_closed
    raise RuntimeError('Event loop is closed')
RuntimeError: Event loop is closed
2022-09-08 16:23:03 [base_events/ERROR]: Fatal error on SSL transport
protocol: <asyncio.sslproto.SSLProtocol object at 0x7ffba305eb60>
transport: <_SelectorSocketTransport closing fd=15>
Traceback (most recent call last):
  File "/usr/local/lib/python3.10/asyncio/selector_events.py", line 916, in write
    n = self._sock.send(data)
OSError: [Errno 9] Bad file descriptor

During handling of the above exception, another exception occurred:

Traceback (most recent call last):
  File "/usr/local/lib/python3.10/asyncio/sslproto.py", line 690, in _process_write_backlog
    self._transport.write(chunk)
  File "/usr/local/lib/python3.10/asyncio/selector_events.py", line 922, in write
    self._fatal_error(exc, 'Fatal write error on socket transport')
  File "/usr/local/lib/python3.10/asyncio/selector_events.py", line 717, in _fatal_error
    self._force_close(exc)
  File "/usr/local/lib/python3.10/asyncio/selector_events.py", line 729, in _force_close
    self._loop.call_soon(self._call_connection_lost, exc)
  File "/usr/local/lib/python3.10/asyncio/base_events.py", line 750, in call_soon
    self._check_closed()
  File "/usr/local/lib/python3.10/asyncio/base_events.py", line 515, in _check_closed
    raise RuntimeError('Event loop is closed')
RuntimeError: Event loop is closed
2022-09-08 16:23:03 [base_events/ERROR]: Fatal error on SSL transport
protocol: <asyncio.sslproto.SSLProtocol object at 0x7ffba0ee87f0>
transport: <_SelectorSocketTransport closing fd=18>
Traceback (most recent call last):
  File "/usr/local/lib/python3.10/asyncio/selector_events.py", line 916, in write
    n = self._sock.send(data)
OSError: [Errno 9] Bad file descriptor

During handling of the above exception, another exception occurred:

Traceback (most recent call last):
  File "/usr/local/lib/python3.10/asyncio/sslproto.py", line 690, in _process_write_backlog
    self._transport.write(chunk)
  File "/usr/local/lib/python3.10/asyncio/selector_events.py", line 922, in write
    self._fatal_error(exc, 'Fatal write error on socket transport')
  File "/usr/local/lib/python3.10/asyncio/selector_events.py", line 717, in _fatal_error
    self._force_close(exc)
  File "/usr/local/lib/python3.10/asyncio/selector_events.py", line 729, in _force_close
    self._loop.call_soon(self._call_connection_lost, exc)
  File "/usr/local/lib/python3.10/asyncio/base_events.py", line 750, in call_soon
    self._check_closed()
  File "/usr/local/lib/python3.10/asyncio/base_events.py", line 515, in _check_closed
    raise RuntimeError('Event loop is closed')
RuntimeError: Event loop is closed
2022-09-08 16:23:03 [base_events/ERROR]: Fatal error on SSL transport
protocol: <asyncio.sslproto.SSLProtocol object at 0x7ffb9a42f8b0>
transport: <_SelectorSocketTransport closing fd=21>
Traceback (most recent call last):
  File "/usr/local/lib/python3.10/asyncio/selector_events.py", line 916, in write
    n = self._sock.send(data)
OSError: [Errno 9] Bad file descriptor

During handling of the above exception, another exception occurred:

Traceback (most recent call last):
  File "/usr/local/lib/python3.10/asyncio/sslproto.py", line 690, in _process_write_backlog
    self._transport.write(chunk)
  File "/usr/local/lib/python3.10/asyncio/selector_events.py", line 922, in write
    self._fatal_error(exc, 'Fatal write error on socket transport')
  File "/usr/local/lib/python3.10/asyncio/selector_events.py", line 717, in _fatal_error
    self._force_close(exc)
  File "/usr/local/lib/python3.10/asyncio/selector_events.py", line 729, in _force_close
    self._loop.call_soon(self._call_connection_lost, exc)
  File "/usr/local/lib/python3.10/asyncio/base_events.py", line 750, in call_soon
    self._check_closed()
  File "/usr/local/lib/python3.10/asyncio/base_events.py", line 515, in _check_closed
    raise RuntimeError('Event loop is closed')
RuntimeError: Event loop is closed
2022-09-08 16:23:03 [base_events/ERROR]: Fatal error on SSL transport
protocol: <asyncio.sslproto.SSLProtocol object at 0x7ffb9a42e890>
transport: <_SelectorSocketTransport closing fd=20>
Traceback (most recent call last):
  File "/usr/local/lib/python3.10/asyncio/selector_events.py", line 916, in write
    n = self._sock.send(data)
OSError: [Errno 9] Bad file descriptor

During handling of the above exception, another exception occurred:

Traceback (most recent call last):
  File "/usr/local/lib/python3.10/asyncio/sslproto.py", line 690, in _process_write_backlog
    self._transport.write(chunk)
  File "/usr/local/lib/python3.10/asyncio/selector_events.py", line 922, in write
    self._fatal_error(exc, 'Fatal write error on socket transport')
  File "/usr/local/lib/python3.10/asyncio/selector_events.py", line 717, in _fatal_error
    self._force_close(exc)
  File "/usr/local/lib/python3.10/asyncio/selector_events.py", line 729, in _force_close
    self._loop.call_soon(self._call_connection_lost, exc)
  File "/usr/local/lib/python3.10/asyncio/base_events.py", line 750, in call_soon
    self._check_closed()
  File "/usr/local/lib/python3.10/asyncio/base_events.py", line 515, in _check_closed
    raise RuntimeError('Event loop is closed')
RuntimeError: Event loop is closed
2022-09-08 16:23:03 [base_events/ERROR]: Fatal error on SSL transport
protocol: <asyncio.sslproto.SSLProtocol object at 0x7ffba0eeb2b0>
transport: <_SelectorSocketTransport closing fd=19>
Traceback (most recent call last):
  File "/usr/local/lib/python3.10/asyncio/selector_events.py", line 916, in write
    n = self._sock.send(data)
OSError: [Errno 9] Bad file descriptor

During handling of the above exception, another exception occurred:

Traceback (most recent call last):
  File "/usr/local/lib/python3.10/asyncio/sslproto.py", line 690, in _process_write_backlog
    self._transport.write(chunk)
  File "/usr/local/lib/python3.10/asyncio/selector_events.py", line 922, in write
    self._fatal_error(exc, 'Fatal write error on socket transport')
  File "/usr/local/lib/python3.10/asyncio/selector_events.py", line 717, in _fatal_error
    self._force_close(exc)
  File "/usr/local/lib/python3.10/asyncio/selector_events.py", line 729, in _force_close
    self._loop.call_soon(self._call_connection_lost, exc)
  File "/usr/local/lib/python3.10/asyncio/base_events.py", line 750, in call_soon
    self._check_closed()
  File "/usr/local/lib/python3.10/asyncio/base_events.py", line 515, in _check_closed
    raise RuntimeError('Event loop is closed')
RuntimeError: Event loop is closed
2022-09-08 16:23:03 [base_events/ERROR]: Fatal error on SSL transport
protocol: <asyncio.sslproto.SSLProtocol object at 0x7ffba101faf0>
transport: <_SelectorSocketTransport closing fd=17>
Traceback (most recent call last):
  File "/usr/local/lib/python3.10/asyncio/selector_events.py", line 916, in write
    n = self._sock.send(data)
OSError: [Errno 9] Bad file descriptor

During handling of the above exception, another exception occurred:

Traceback (most recent call last):
  File "/usr/local/lib/python3.10/asyncio/sslproto.py", line 690, in _process_write_backlog
    self._transport.write(chunk)
  File "/usr/local/lib/python3.10/asyncio/selector_events.py", line 922, in write
    self._fatal_error(exc, 'Fatal write error on socket transport')
  File "/usr/local/lib/python3.10/asyncio/selector_events.py", line 717, in _fatal_error
    self._force_close(exc)
  File "/usr/local/lib/python3.10/asyncio/selector_events.py", line 729, in _force_close
    self._loop.call_soon(self._call_connection_lost, exc)
  File "/usr/local/lib/python3.10/asyncio/base_events.py", line 750, in call_soon
    self._check_closed()
  File "/usr/local/lib/python3.10/asyncio/base_events.py", line 515, in _check_closed
    raise RuntimeError('Event loop is closed')
RuntimeError: Event loop is closed
2022-09-08 16:23:03 [base_events/ERROR]: Fatal error on SSL transport
protocol: <asyncio.sslproto.SSLProtocol object at 0x7ffba0eea3b0>
transport: <_SelectorSocketTransport closing fd=22>
Traceback (most recent call last):
  File "/usr/local/lib/python3.10/asyncio/selector_events.py", line 916, in write
    n = self._sock.send(data)
OSError: [Errno 9] Bad file descriptor

During handling of the above exception, another exception occurred:

Traceback (most recent call last):
  File "/usr/local/lib/python3.10/asyncio/sslproto.py", line 690, in _process_write_backlog
    self._transport.write(chunk)
  File "/usr/local/lib/python3.10/asyncio/selector_events.py", line 922, in write
    self._fatal_error(exc, 'Fatal write error on socket transport')
  File "/usr/local/lib/python3.10/asyncio/selector_events.py", line 717, in _fatal_error
    self._force_close(exc)
  File "/usr/local/lib/python3.10/asyncio/selector_events.py", line 729, in _force_close
    self._loop.call_soon(self._call_connection_lost, exc)
  File "/usr/local/lib/python3.10/asyncio/base_events.py", line 750, in call_soon
    self._check_closed()
  File "/usr/local/lib/python3.10/asyncio/base_events.py", line 515, in _check_closed
    raise RuntimeError('Event loop is closed')
RuntimeError: Event loop is closed
2022-09-08 16:23:03 [base_events/ERROR]: Unclosed client session
client_session: <aiohttp.client.ClientSession object at 0x7ffba0ee8670>
2022-09-08 16:23:03 [base_events/ERROR]: Unclosed client session
client_session: <aiohttp.client.ClientSession object at 0x7ffba0ee9120>
2022-09-08 16:23:03 [base_events/ERROR]: Unclosed client session
client_session: <aiohttp.client.ClientSession object at 0x7ffba107d4e0>
2022-09-08 16:23:03 [base_events/ERROR]: Unclosed client session
client_session: <aiohttp.client.ClientSession object at 0x7ffba0ee95d0>
2022-09-08 16:23:03 [base_events/ERROR]: Task was destroyed but it is pending!
task: <Task pending name='Task-9600' coro=<Throttler.looper() running at /usr/local/lib/python3.10/site-packages/ccxt/async_support/base/throttler.py:36> wait_for=<Future pending cb=[Task.task_wakeup()]>>
2022-09-08 16:23:03 [base_events/ERROR]: Task was destroyed but it is pending!
task: <Task pending name='Task-9603' coro=<Throttler.looper() running at /usr/local/lib/python3.10/site-packages/ccxt/async_support/base/throttler.py:36> wait_for=<Future pending cb=[Task.task_wakeup()]>>
2022-09-08 16:23:03 [base_events/ERROR]: Task was destroyed but it is pending!
task: <Task pending name='Task-9610' coro=<Throttler.looper() running at /usr/local/lib/python3.10/site-packages/ccxt/async_support/base/throttler.py:36> wait_for=<Future pending cb=[Task.task_wakeup()]>>
2022-09-08 16:23:03 [base_events/ERROR]: Task was destroyed but it is pending!
task: <Task pending name='Task-9687' coro=<Throttler.looper() running at /usr/local/lib/python3.10/site-packages/ccxt/async_support/base/throttler.py:36> wait_for=<Future pending cb=[Task.task_wakeup()]>>
2022-09-08 16:23:03 [base_events/ERROR]: Task was destroyed but it is pending!
task: <Task pending name='Task-9690' coro=<Throttler.looper() running at /usr/local/lib/python3.10/site-packages/ccxt/async_support/base/throttler.py:36> wait_for=<Future pending cb=[Task.task_wakeup()]>>
2022-09-08 16:23:03 [base_events/ERROR]: Task was destroyed but it is pending!
task: <Task pending name='Task-9691' coro=<Throttler.looper() running at /usr/local/lib/python3.10/site-packages/ccxt/async_support/base/throttler.py:36> wait_for=<Future pending cb=[Task.task_wakeup()]>>
2022-09-08 16:23:03 [base_events/ERROR]: Unclosed client session
client_session: <aiohttp.client.ClientSession object at 0x7ffba0eebd00>
2022-09-08 16:23:03 [base_events/ERROR]: Unclosed connector
connections: ['[(<aiohttp.client_proto.ResponseHandler object at 0x7ffb98d33e20>, 1267.496701778)]']
connector: <aiohttp.connector.TCPConnector object at 0x7ffba0eeb400>
2022-09-08 16:23:03 [base_events/ERROR]: Unclosed client session
client_session: <aiohttp.client.ClientSession object at 0x7ffba0ee80a0>
2022-09-08 16:23:03 [base_events/ERROR]: Unclosed connector
connections: ['[(<aiohttp.client_proto.ResponseHandler object at 0x7ffba0ee5f00>, 1265.880037253)]']
connector: <aiohttp.connector.TCPConnector object at 0x7ffba305f2e0>
2022-09-08 16:23:03 [base_events/ERROR]: Unclosed client session
client_session: <aiohttp.client.ClientSession object at 0x7ffba0ee94e0>
2022-09-08 16:23:03 [base_events/ERROR]: Unclosed connector
connections: ['[(<aiohttp.client_proto.ResponseHandler object at 0x7ffba0ee5660>, 1265.806190494)]']
connector: <aiohttp.connector.TCPConnector object at 0x7ffba101da50>
2022-09-08 16:23:03 [base_events/ERROR]: Unclosed client session
client_session: <aiohttp.client.ClientSession object at 0x7ffb9a42e9e0>
2022-09-08 16:23:03 [base_events/ERROR]: Unclosed connector
connections: ['[(<aiohttp.client_proto.ResponseHandler object at 0x7ffb98d31ae0>, 1265.849001561)]']
connector: <aiohttp.connector.TCPConnector object at 0x7ffba305e6b0>
2022-09-08 16:23:03 [base_events/ERROR]: Unclosed client session
client_session: <aiohttp.client.ClientSession object at 0x7ffba0ee9210>
2022-09-08 16:23:03 [base_events/ERROR]: Unclosed connector
connections: ['[(<aiohttp.client_proto.ResponseHandler object at 0x7ffba0ee62c0>, 1265.883137259)]']
connector: <aiohttp.connector.TCPConnector object at 0x7ffba305eb00>
2022-09-08 16:23:03 [base_events/ERROR]: Unclosed client session
client_session: <aiohttp.client.ClientSession object at 0x7ffba101f7f0>
2022-09-08 16:23:03 [base_events/ERROR]: Unclosed connector
connections: ['[(<aiohttp.client_proto.ResponseHandler object at 0x7ffb98d332e0>, 1265.935758238)]']
connector: <aiohttp.connector.TCPConnector object at 0x7ffba0ee9780>
2022-09-08 16:23:03 [base_events/ERROR]: Unclosed client session
client_session: <aiohttp.client.ClientSession object at 0x7ffba107f6a0>
2022-09-08 16:23:03 [base_events/ERROR]: Unclosed connector
connections: ['[(<aiohttp.client_proto.ResponseHandler object at 0x7ffba0ee6c20>, 1264.823176775)]']
connector: <aiohttp.connector.TCPConnector object at 0x7ffba305f070>
2022-09-08 16:23:03 [base_events/ERROR]: Unclosed client session
client_session: <aiohttp.client.ClientSession object at 0x7ffba107e830>
2022-09-08 16:23:03 [base_events/ERROR]: Unclosed connector
connections: ['[(<aiohttp.client_proto.ResponseHandler object at 0x7ffb98d32ec0>, 1267.419133142)]']
connector: <aiohttp.connector.TCPConnector object at 0x7ffba0eeb4c0>
2022-09-08 16:23:03 [base_events/ERROR]: Unclosed client session
client_session: <aiohttp.client.ClientSession object at 0x7ffba0eeba00>
2022-09-08 16:23:03 [base_events/ERROR]: Unclosed connector
connections: ['[(<aiohttp.client_proto.ResponseHandler object at 0x7ffba1029420>, 1267.417068164)]']
connector: <aiohttp.connector.TCPConnector object at 0x7ffba305e650>
2022-09-08 16:23:04 [base_events/ERROR]: Unclosed client session
client_session: <aiohttp.client.ClientSession object at 0x7ffba107ed70>
2022-09-08 16:23:04 [base_events/ERROR]: Unclosed connector
connections: ['[(<aiohttp.client_proto.ResponseHandler object at 0x7ffb98d323e0>, 1267.451347459)]']
connector: <aiohttp.connector.TCPConnector object at 0x7ffba305f430>
2022-09-08 16:23:04 [base_events/ERROR]: Unclosed client session
client_session: <aiohttp.client.ClientSession object at 0x7ffba0eebfa0>
2022-09-08 16:23:04 [base_events/ERROR]: Unclosed connector
connections: ['[(<aiohttp.client_proto.ResponseHandler object at 0x7ffb98d314e0>, 1266.118576273)]']
connector: <aiohttp.connector.TCPConnector object at 0x7ffba305e5c0>
2022-09-08 16:25:27 [base_events/ERROR]: Fatal error on SSL transport
protocol: <asyncio.sslproto.SSLProtocol object at 0x7f78bf9fe020>
transport: <_SelectorSocketTransport closing fd=9>
Traceback (most recent call last):
  File "/usr/local/lib/python3.10/asyncio/selector_events.py", line 916, in write
    n = self._sock.send(data)
OSError: [Errno 9] Bad file descriptor

During handling of the above exception, another exception occurred:

Traceback (most recent call last):
  File "/usr/local/lib/python3.10/asyncio/sslproto.py", line 690, in _process_write_backlog
    self._transport.write(chunk)
  File "/usr/local/lib/python3.10/asyncio/selector_events.py", line 922, in write
    self._fatal_error(exc, 'Fatal write error on socket transport')
  File "/usr/local/lib/python3.10/asyncio/selector_events.py", line 717, in _fatal_error
    self._force_close(exc)
  File "/usr/local/lib/python3.10/asyncio/selector_events.py", line 729, in _force_close
    self._loop.call_soon(self._call_connection_lost, exc)
  File "/usr/local/lib/python3.10/asyncio/base_events.py", line 750, in call_soon
    self._check_closed()
  File "/usr/local/lib/python3.10/asyncio/base_events.py", line 515, in _check_closed
    raise RuntimeError('Event loop is closed')
RuntimeError: Event loop is closed
2022-09-08 16:25:27 [base_events/ERROR]: Fatal error on SSL transport
protocol: <asyncio.sslproto.SSLProtocol object at 0x7f78bf9fe4a0>
transport: <_SelectorSocketTransport closing fd=8>
Traceback (most recent call last):
  File "/usr/local/lib/python3.10/asyncio/selector_events.py", line 916, in write
    n = self._sock.send(data)
OSError: [Errno 9] Bad file descriptor

During handling of the above exception, another exception occurred:

Traceback (most recent call last):
  File "/usr/local/lib/python3.10/asyncio/sslproto.py", line 690, in _process_write_backlog
    self._transport.write(chunk)
  File "/usr/local/lib/python3.10/asyncio/selector_events.py", line 922, in write
    self._fatal_error(exc, 'Fatal write error on socket transport')
  File "/usr/local/lib/python3.10/asyncio/selector_events.py", line 717, in _fatal_error
    self._force_close(exc)
  File "/usr/local/lib/python3.10/asyncio/selector_events.py", line 729, in _force_close
    self._loop.call_soon(self._call_connection_lost, exc)
  File "/usr/local/lib/python3.10/asyncio/base_events.py", line 750, in call_soon
    self._check_closed()
  File "/usr/local/lib/python3.10/asyncio/base_events.py", line 515, in _check_closed
    raise RuntimeError('Event loop is closed')
RuntimeError: Event loop is closed
2022-09-08 16:25:27 [base_events/ERROR]: Unclosed client session
client_session: <aiohttp.client.ClientSession object at 0x7f78bf9fd0f0>
2022-09-08 16:25:27 [base_events/ERROR]: Task was destroyed but it is pending!
task: <Task pending name='Task-501' coro=<Throttler.looper() running at /usr/local/lib/python3.10/site-packages/ccxt/async_support/base/throttler.py:36> wait_for=<Future pending cb=[Task.task_wakeup()]>>
2022-09-08 16:25:27 [base_events/ERROR]: Unclosed client session
client_session: <aiohttp.client.ClientSession object at 0x7f78bf9fd4b0>
2022-09-08 16:25:27 [base_events/ERROR]: Unclosed connector
connections: ['[(<aiohttp.client_proto.ResponseHandler object at 0x7f78bf9f8880>, 1408.918783863)]']
connector: <aiohttp.connector.TCPConnector object at 0x7f78bfb31a20>
2022-09-08 16:27:36 [base_events/ERROR]: Fatal error on SSL transport
protocol: <asyncio.sslproto.SSLProtocol object at 0x7f243f522110>
transport: <_SelectorSocketTransport closing fd=10>
Traceback (most recent call last):
  File "/usr/local/lib/python3.10/asyncio/selector_events.py", line 916, in write
    n = self._sock.send(data)
OSError: [Errno 9] Bad file descriptor

During handling of the above exception, another exception occurred:

Traceback (most recent call last):
  File "/usr/local/lib/python3.10/asyncio/sslproto.py", line 690, in _process_write_backlog
    self._transport.write(chunk)
  File "/usr/local/lib/python3.10/asyncio/selector_events.py", line 922, in write
    self._fatal_error(exc, 'Fatal write error on socket transport')
  File "/usr/local/lib/python3.10/asyncio/selector_events.py", line 717, in _fatal_error
    self._force_close(exc)
  File "/usr/local/lib/python3.10/asyncio/selector_events.py", line 729, in _force_close
    self._loop.call_soon(self._call_connection_lost, exc)
  File "/usr/local/lib/python3.10/asyncio/base_events.py", line 750, in call_soon
    self._check_closed()
  File "/usr/local/lib/python3.10/asyncio/base_events.py", line 515, in _check_closed
    raise RuntimeError('Event loop is closed')
RuntimeError: Event loop is closed
2022-09-08 16:27:36 [base_events/ERROR]: Task was destroyed but it is pending!
task: <Task pending name='Task-137' coro=<Throttler.looper() running at /usr/local/lib/python3.10/site-packages/ccxt/async_support/base/throttler.py:36> wait_for=<Future pending cb=[Task.task_wakeup()]>>
2022-09-08 16:27:36 [base_events/ERROR]: Fatal error on SSL transport
protocol: <asyncio.sslproto.SSLProtocol object at 0x7f243f522590>
transport: <_SelectorSocketTransport closing fd=8>
Traceback (most recent call last):
  File "/usr/local/lib/python3.10/asyncio/selector_events.py", line 916, in write
    n = self._sock.send(data)
OSError: [Errno 9] Bad file descriptor

During handling of the above exception, another exception occurred:

Traceback (most recent call last):
  File "/usr/local/lib/python3.10/asyncio/sslproto.py", line 690, in _process_write_backlog
    self._transport.write(chunk)
  File "/usr/local/lib/python3.10/asyncio/selector_events.py", line 922, in write
    self._fatal_error(exc, 'Fatal write error on socket transport')
  File "/usr/local/lib/python3.10/asyncio/selector_events.py", line 717, in _fatal_error
    self._force_close(exc)
  File "/usr/local/lib/python3.10/asyncio/selector_events.py", line 729, in _force_close
    self._loop.call_soon(self._call_connection_lost, exc)
  File "/usr/local/lib/python3.10/asyncio/base_events.py", line 750, in call_soon
    self._check_closed()
  File "/usr/local/lib/python3.10/asyncio/base_events.py", line 515, in _check_closed
    raise RuntimeError('Event loop is closed')
RuntimeError: Event loop is closed
2022-09-08 16:27:36 [base_events/ERROR]: Fatal error on SSL transport
protocol: <asyncio.sslproto.SSLProtocol object at 0x7f243f521960>
transport: <_SelectorSocketTransport closing fd=9>
Traceback (most recent call last):
  File "/usr/local/lib/python3.10/asyncio/selector_events.py", line 916, in write
    n = self._sock.send(data)
OSError: [Errno 9] Bad file descriptor

During handling of the above exception, another exception occurred:

Traceback (most recent call last):
  File "/usr/local/lib/python3.10/asyncio/sslproto.py", line 690, in _process_write_backlog
    self._transport.write(chunk)
  File "/usr/local/lib/python3.10/asyncio/selector_events.py", line 922, in write
    self._fatal_error(exc, 'Fatal write error on socket transport')
  File "/usr/local/lib/python3.10/asyncio/selector_events.py", line 717, in _fatal_error
    self._force_close(exc)
  File "/usr/local/lib/python3.10/asyncio/selector_events.py", line 729, in _force_close
    self._loop.call_soon(self._call_connection_lost, exc)
  File "/usr/local/lib/python3.10/asyncio/base_events.py", line 750, in call_soon
    self._check_closed()
  File "/usr/local/lib/python3.10/asyncio/base_events.py", line 515, in _check_closed
    raise RuntimeError('Event loop is closed')
RuntimeError: Event loop is closed
2022-09-08 16:27:36 [base_events/ERROR]: Unclosed client session
client_session: <aiohttp.client.ClientSession object at 0x7f243f5211e0>
2022-09-08 16:27:36 [base_events/ERROR]: Unclosed connector
connections: ['[(<aiohttp.client_proto.ResponseHandler object at 0x7f243f51d9c0>, 1540.626019505)]']
connector: <aiohttp.connector.TCPConnector object at 0x7f243f4efd60>
2022-09-08 16:27:36 [base_events/ERROR]: Unclosed client session
client_session: <aiohttp.client.ClientSession object at 0x7f243f5215a0>
2022-09-08 16:27:36 [base_events/ERROR]: Unclosed connector
connections: ['[(<aiohttp.client_proto.ResponseHandler object at 0x7f243f51c8e0>, 1538.958007441)]']
connector: <aiohttp.connector.TCPConnector object at 0x7f243f64db10>
2022-09-08 16:27:36 [base_events/ERROR]: Unclosed client session
client_session: <aiohttp.client.ClientSession object at 0x7f243f520e80>
2022-09-08 16:34:39 [base_events/ERROR]: Fatal error on SSL transport
protocol: <asyncio.sslproto.SSLProtocol object at 0x7f29a0ffcf40>
transport: <_SelectorSocketTransport closing fd=9>
Traceback (most recent call last):
  File "/usr/local/lib/python3.10/asyncio/selector_events.py", line 916, in write
    n = self._sock.send(data)
OSError: [Errno 9] Bad file descriptor

During handling of the above exception, another exception occurred:

Traceback (most recent call last):
  File "/usr/local/lib/python3.10/asyncio/sslproto.py", line 690, in _process_write_backlog
    self._transport.write(chunk)
  File "/usr/local/lib/python3.10/asyncio/selector_events.py", line 922, in write
    self._fatal_error(exc, 'Fatal write error on socket transport')
  File "/usr/local/lib/python3.10/asyncio/selector_events.py", line 717, in _fatal_error
    self._force_close(exc)
  File "/usr/local/lib/python3.10/asyncio/selector_events.py", line 729, in _force_close
    self._loop.call_soon(self._call_connection_lost, exc)
  File "/usr/local/lib/python3.10/asyncio/base_events.py", line 750, in call_soon
    self._check_closed()
  File "/usr/local/lib/python3.10/asyncio/base_events.py", line 515, in _check_closed
    raise RuntimeError('Event loop is closed')
RuntimeError: Event loop is closed
2022-09-08 16:34:39 [base_events/ERROR]: Fatal error on SSL transport
protocol: <asyncio.sslproto.SSLProtocol object at 0x7f29a0ffd3f0>
transport: <_SelectorSocketTransport closing fd=10>
Traceback (most recent call last):
  File "/usr/local/lib/python3.10/asyncio/selector_events.py", line 916, in write
    n = self._sock.send(data)
OSError: [Errno 9] Bad file descriptor

During handling of the above exception, another exception occurred:

Traceback (most recent call last):
  File "/usr/local/lib/python3.10/asyncio/sslproto.py", line 690, in _process_write_backlog
    self._transport.write(chunk)
  File "/usr/local/lib/python3.10/asyncio/selector_events.py", line 922, in write
    self._fatal_error(exc, 'Fatal write error on socket transport')
  File "/usr/local/lib/python3.10/asyncio/selector_events.py", line 717, in _fatal_error
    self._force_close(exc)
  File "/usr/local/lib/python3.10/asyncio/selector_events.py", line 729, in _force_close
    self._loop.call_soon(self._call_connection_lost, exc)
  File "/usr/local/lib/python3.10/asyncio/base_events.py", line 750, in call_soon
    self._check_closed()
  File "/usr/local/lib/python3.10/asyncio/base_events.py", line 515, in _check_closed
    raise RuntimeError('Event loop is closed')
RuntimeError: Event loop is closed
2022-09-08 16:34:39 [base_events/ERROR]: Fatal error on SSL transport
protocol: <asyncio.sslproto.SSLProtocol object at 0x7f29a0ffca60>
transport: <_SelectorSocketTransport closing fd=8>
Traceback (most recent call last):
  File "/usr/local/lib/python3.10/asyncio/selector_events.py", line 916, in write
    n = self._sock.send(data)
OSError: [Errno 9] Bad file descriptor

During handling of the above exception, another exception occurred:

Traceback (most recent call last):
  File "/usr/local/lib/python3.10/asyncio/sslproto.py", line 690, in _process_write_backlog
    self._transport.write(chunk)
  File "/usr/local/lib/python3.10/asyncio/selector_events.py", line 922, in write
    self._fatal_error(exc, 'Fatal write error on socket transport')
  File "/usr/local/lib/python3.10/asyncio/selector_events.py", line 717, in _fatal_error
    self._force_close(exc)
  File "/usr/local/lib/python3.10/asyncio/selector_events.py", line 729, in _force_close
    self._loop.call_soon(self._call_connection_lost, exc)
  File "/usr/local/lib/python3.10/asyncio/base_events.py", line 750, in call_soon
    self._check_closed()
  File "/usr/local/lib/python3.10/asyncio/base_events.py", line 515, in _check_closed
    raise RuntimeError('Event loop is closed')
RuntimeError: Event loop is closed
2022-09-08 16:34:39 [base_events/ERROR]: Unclosed client session
client_session: <aiohttp.client.ClientSession object at 0x7f29a0fb98a0>
2022-09-08 16:34:39 [base_events/ERROR]: Unclosed client session
client_session: <aiohttp.client.ClientSession object at 0x7f29a0fb94e0>
2022-09-08 16:34:39 [base_events/ERROR]: Unclosed client session
client_session: <aiohttp.client.ClientSession object at 0x7f29a0fb9180>
2022-09-08 16:35:53 [base_events/ERROR]: Fatal error on SSL transport
protocol: <asyncio.sslproto.SSLProtocol object at 0x7f4578132050>
transport: <_SelectorSocketTransport closing fd=10>
Traceback (most recent call last):
  File "/usr/local/lib/python3.10/asyncio/selector_events.py", line 916, in write
    n = self._sock.send(data)
OSError: [Errno 9] Bad file descriptor

During handling of the above exception, another exception occurred:

Traceback (most recent call last):
  File "/usr/local/lib/python3.10/asyncio/sslproto.py", line 690, in _process_write_backlog
    self._transport.write(chunk)
  File "/usr/local/lib/python3.10/asyncio/selector_events.py", line 922, in write
    self._fatal_error(exc, 'Fatal write error on socket transport')
  File "/usr/local/lib/python3.10/asyncio/selector_events.py", line 717, in _fatal_error
    self._force_close(exc)
  File "/usr/local/lib/python3.10/asyncio/selector_events.py", line 729, in _force_close
    self._loop.call_soon(self._call_connection_lost, exc)
  File "/usr/local/lib/python3.10/asyncio/base_events.py", line 750, in call_soon
    self._check_closed()
  File "/usr/local/lib/python3.10/asyncio/base_events.py", line 515, in _check_closed
    raise RuntimeError('Event loop is closed')
RuntimeError: Event loop is closed
2022-09-08 16:35:53 [base_events/ERROR]: Fatal error on SSL transport
protocol: <asyncio.sslproto.SSLProtocol object at 0x7f4578131420>
transport: <_SelectorSocketTransport closing fd=8>
Traceback (most recent call last):
  File "/usr/local/lib/python3.10/asyncio/selector_events.py", line 916, in write
    n = self._sock.send(data)
OSError: [Errno 9] Bad file descriptor

During handling of the above exception, another exception occurred:

Traceback (most recent call last):
  File "/usr/local/lib/python3.10/asyncio/sslproto.py", line 690, in _process_write_backlog
    self._transport.write(chunk)
  File "/usr/local/lib/python3.10/asyncio/selector_events.py", line 922, in write
    self._fatal_error(exc, 'Fatal write error on socket transport')
  File "/usr/local/lib/python3.10/asyncio/selector_events.py", line 717, in _fatal_error
    self._force_close(exc)
  File "/usr/local/lib/python3.10/asyncio/selector_events.py", line 729, in _force_close
    self._loop.call_soon(self._call_connection_lost, exc)
  File "/usr/local/lib/python3.10/asyncio/base_events.py", line 750, in call_soon
    self._check_closed()
  File "/usr/local/lib/python3.10/asyncio/base_events.py", line 515, in _check_closed
    raise RuntimeError('Event loop is closed')
RuntimeError: Event loop is closed
2022-09-08 16:35:53 [base_events/ERROR]: Task was destroyed but it is pending!
task: <Task pending name='Task-43' coro=<Throttler.looper() running at /usr/local/lib/python3.10/site-packages/ccxt/async_support/base/throttler.py:36> wait_for=<Future pending cb=[Task.task_wakeup()]>>
2022-09-08 16:35:53 [base_events/ERROR]: Fatal error on SSL transport
protocol: <asyncio.sslproto.SSLProtocol object at 0x7f4578132530>
transport: <_SelectorSocketTransport closing fd=9>
Traceback (most recent call last):
  File "/usr/local/lib/python3.10/asyncio/selector_events.py", line 916, in write
    n = self._sock.send(data)
OSError: [Errno 9] Bad file descriptor

During handling of the above exception, another exception occurred:

Traceback (most recent call last):
  File "/usr/local/lib/python3.10/asyncio/sslproto.py", line 690, in _process_write_backlog
    self._transport.write(chunk)
  File "/usr/local/lib/python3.10/asyncio/selector_events.py", line 922, in write
    self._fatal_error(exc, 'Fatal write error on socket transport')
  File "/usr/local/lib/python3.10/asyncio/selector_events.py", line 717, in _fatal_error
    self._force_close(exc)
  File "/usr/local/lib/python3.10/asyncio/selector_events.py", line 729, in _force_close
    self._loop.call_soon(self._call_connection_lost, exc)
  File "/usr/local/lib/python3.10/asyncio/base_events.py", line 750, in call_soon
    self._check_closed()
  File "/usr/local/lib/python3.10/asyncio/base_events.py", line 515, in _check_closed
    raise RuntimeError('Event loop is closed')
RuntimeError: Event loop is closed
2022-09-08 16:35:53 [base_events/ERROR]: Unclosed client session
client_session: <aiohttp.client.ClientSession object at 0x7f4578131120>
2022-09-08 16:35:53 [base_events/ERROR]: Unclosed connector
connections: ['[(<aiohttp.client_proto.ResponseHandler object at 0x7f457812d540>, 2038.524441676)]']
connector: <aiohttp.connector.TCPConnector object at 0x7f45780ffca0>
2022-09-08 16:35:53 [base_events/ERROR]: Unclosed client session
client_session: <aiohttp.client.ClientSession object at 0x7f4578130dc0>
2022-09-08 16:35:53 [base_events/ERROR]: Unclosed client session
client_session: <aiohttp.client.ClientSession object at 0x7f45781314e0>
2022-09-08 16:35:53 [base_events/ERROR]: Unclosed connector
connections: ['[(<aiohttp.client_proto.ResponseHandler object at 0x7f457812d660>, 2036.095650676)]']
connector: <aiohttp.connector.TCPConnector object at 0x7f4578265a50>
2022-09-08 16:39:38 [base_events/ERROR]: Fatal error on SSL transport
protocol: <asyncio.sslproto.SSLProtocol object at 0x7f6b20c2e1a0>
transport: <_SelectorSocketTransport closing fd=9>
Traceback (most recent call last):
  File "/usr/local/lib/python3.10/asyncio/selector_events.py", line 916, in write
    n = self._sock.send(data)
OSError: [Errno 9] Bad file descriptor

During handling of the above exception, another exception occurred:

Traceback (most recent call last):
  File "/usr/local/lib/python3.10/asyncio/sslproto.py", line 690, in _process_write_backlog
    self._transport.write(chunk)
  File "/usr/local/lib/python3.10/asyncio/selector_events.py", line 922, in write
    self._fatal_error(exc, 'Fatal write error on socket transport')
  File "/usr/local/lib/python3.10/asyncio/selector_events.py", line 717, in _fatal_error
    self._force_close(exc)
  File "/usr/local/lib/python3.10/asyncio/selector_events.py", line 729, in _force_close
    self._loop.call_soon(self._call_connection_lost, exc)
  File "/usr/local/lib/python3.10/asyncio/base_events.py", line 750, in call_soon
    self._check_closed()
  File "/usr/local/lib/python3.10/asyncio/base_events.py", line 515, in _check_closed
    raise RuntimeError('Event loop is closed')
RuntimeError: Event loop is closed
2022-09-08 16:39:38 [base_events/ERROR]: Fatal error on SSL transport
protocol: <asyncio.sslproto.SSLProtocol object at 0x7f6b20c2e620>
transport: <_SelectorSocketTransport closing fd=8>
Traceback (most recent call last):
  File "/usr/local/lib/python3.10/asyncio/selector_events.py", line 916, in write
    n = self._sock.send(data)
OSError: [Errno 9] Bad file descriptor

During handling of the above exception, another exception occurred:

Traceback (most recent call last):
  File "/usr/local/lib/python3.10/asyncio/sslproto.py", line 690, in _process_write_backlog
    self._transport.write(chunk)
  File "/usr/local/lib/python3.10/asyncio/selector_events.py", line 922, in write
    self._fatal_error(exc, 'Fatal write error on socket transport')
  File "/usr/local/lib/python3.10/asyncio/selector_events.py", line 717, in _fatal_error
    self._force_close(exc)
  File "/usr/local/lib/python3.10/asyncio/selector_events.py", line 729, in _force_close
    self._loop.call_soon(self._call_connection_lost, exc)
  File "/usr/local/lib/python3.10/asyncio/base_events.py", line 750, in call_soon
    self._check_closed()
  File "/usr/local/lib/python3.10/asyncio/base_events.py", line 515, in _check_closed
    raise RuntimeError('Event loop is closed')
RuntimeError: Event loop is closed
2022-09-08 16:39:38 [base_events/ERROR]: Fatal error on SSL transport
protocol: <asyncio.sslproto.SSLProtocol object at 0x7f6b20c2d9f0>
transport: <_SelectorSocketTransport closing fd=10>
Traceback (most recent call last):
  File "/usr/local/lib/python3.10/asyncio/selector_events.py", line 916, in write
    n = self._sock.send(data)
OSError: [Errno 9] Bad file descriptor

During handling of the above exception, another exception occurred:

Traceback (most recent call last):
  File "/usr/local/lib/python3.10/asyncio/sslproto.py", line 690, in _process_write_backlog
    self._transport.write(chunk)
  File "/usr/local/lib/python3.10/asyncio/selector_events.py", line 922, in write
    self._fatal_error(exc, 'Fatal write error on socket transport')
  File "/usr/local/lib/python3.10/asyncio/selector_events.py", line 717, in _fatal_error
    self._force_close(exc)
  File "/usr/local/lib/python3.10/asyncio/selector_events.py", line 729, in _force_close
    self._loop.call_soon(self._call_connection_lost, exc)
  File "/usr/local/lib/python3.10/asyncio/base_events.py", line 750, in call_soon
    self._check_closed()
  File "/usr/local/lib/python3.10/asyncio/base_events.py", line 515, in _check_closed
    raise RuntimeError('Event loop is closed')
RuntimeError: Event loop is closed
2022-09-08 16:39:38 [base_events/ERROR]: Unclosed client session
client_session: <aiohttp.client.ClientSession object at 0x7f6b20c2d270>
2022-09-08 16:39:38 [base_events/ERROR]: Unclosed connector
connections: ['[(<aiohttp.client_proto.ResponseHandler object at 0x7f6b20c28a60>, 2263.721226732)]']
connector: <aiohttp.connector.TCPConnector object at 0x7f6b20bfbdf0>
2022-09-08 16:39:38 [base_events/ERROR]: Unclosed client session
client_session: <aiohttp.client.ClientSession object at 0x7f6b20c2d630>
2022-09-08 16:39:38 [base_events/ERROR]: Unclosed client session
client_session: <aiohttp.client.ClientSession object at 0x7f6b20c2cf10>
2022-09-08 16:41:25 [base_events/ERROR]: Fatal error on SSL transport
protocol: <asyncio.sslproto.SSLProtocol object at 0x7faa5e085a20>
transport: <_SelectorSocketTransport closing fd=8>
Traceback (most recent call last):
  File "/usr/local/lib/python3.10/asyncio/selector_events.py", line 916, in write
    n = self._sock.send(data)
OSError: [Errno 9] Bad file descriptor

During handling of the above exception, another exception occurred:

Traceback (most recent call last):
  File "/usr/local/lib/python3.10/asyncio/sslproto.py", line 690, in _process_write_backlog
    self._transport.write(chunk)
  File "/usr/local/lib/python3.10/asyncio/selector_events.py", line 922, in write
    self._fatal_error(exc, 'Fatal write error on socket transport')
  File "/usr/local/lib/python3.10/asyncio/selector_events.py", line 717, in _fatal_error
    self._force_close(exc)
  File "/usr/local/lib/python3.10/asyncio/selector_events.py", line 729, in _force_close
    self._loop.call_soon(self._call_connection_lost, exc)
  File "/usr/local/lib/python3.10/asyncio/base_events.py", line 750, in call_soon
    self._check_closed()
  File "/usr/local/lib/python3.10/asyncio/base_events.py", line 515, in _check_closed
    raise RuntimeError('Event loop is closed')
RuntimeError: Event loop is closed
2022-09-08 16:41:25 [base_events/ERROR]: Fatal error on SSL transport
protocol: <asyncio.sslproto.SSLProtocol object at 0x7faa5e0862c0>
transport: <_SelectorSocketTransport closing fd=9>
Traceback (most recent call last):
  File "/usr/local/lib/python3.10/asyncio/selector_events.py", line 916, in write
    n = self._sock.send(data)
OSError: [Errno 9] Bad file descriptor

During handling of the above exception, another exception occurred:

Traceback (most recent call last):
  File "/usr/local/lib/python3.10/asyncio/sslproto.py", line 690, in _process_write_backlog
    self._transport.write(chunk)
  File "/usr/local/lib/python3.10/asyncio/selector_events.py", line 922, in write
    self._fatal_error(exc, 'Fatal write error on socket transport')
  File "/usr/local/lib/python3.10/asyncio/selector_events.py", line 717, in _fatal_error
    self._force_close(exc)
  File "/usr/local/lib/python3.10/asyncio/selector_events.py", line 729, in _force_close
    self._loop.call_soon(self._call_connection_lost, exc)
  File "/usr/local/lib/python3.10/asyncio/base_events.py", line 750, in call_soon
    self._check_closed()
  File "/usr/local/lib/python3.10/asyncio/base_events.py", line 515, in _check_closed
    raise RuntimeError('Event loop is closed')
RuntimeError: Event loop is closed
2022-09-08 16:41:25 [base_events/ERROR]: Task was destroyed but it is pending!
task: <Task pending name='Task-17' coro=<Throttler.looper() running at /usr/local/lib/python3.10/site-packages/ccxt/async_support/base/throttler.py:36> wait_for=<Future pending cb=[Task.task_wakeup()]>>
2022-09-08 16:41:25 [base_events/ERROR]: Fatal error on SSL transport
protocol: <asyncio.sslproto.SSLProtocol object at 0x7faa5e0860b0>
transport: <_SelectorSocketTransport closing fd=10>
Traceback (most recent call last):
  File "/usr/local/lib/python3.10/asyncio/selector_events.py", line 916, in write
    n = self._sock.send(data)
OSError: [Errno 9] Bad file descriptor

During handling of the above exception, another exception occurred:

Traceback (most recent call last):
  File "/usr/local/lib/python3.10/asyncio/sslproto.py", line 690, in _process_write_backlog
    self._transport.write(chunk)
  File "/usr/local/lib/python3.10/asyncio/selector_events.py", line 922, in write
    self._fatal_error(exc, 'Fatal write error on socket transport')
  File "/usr/local/lib/python3.10/asyncio/selector_events.py", line 717, in _fatal_error
    self._force_close(exc)
  File "/usr/local/lib/python3.10/asyncio/selector_events.py", line 729, in _force_close
    self._loop.call_soon(self._call_connection_lost, exc)
  File "/usr/local/lib/python3.10/asyncio/base_events.py", line 750, in call_soon
    self._check_closed()
  File "/usr/local/lib/python3.10/asyncio/base_events.py", line 515, in _check_closed
    raise RuntimeError('Event loop is closed')
RuntimeError: Event loop is closed
2022-09-08 16:41:25 [base_events/ERROR]: Unclosed client session
client_session: <aiohttp.client.ClientSession object at 0x7faa5e0852a0>
2022-09-08 16:41:25 [base_events/ERROR]: Unclosed client session
client_session: <aiohttp.client.ClientSession object at 0x7faa5e084f40>
2022-09-08 16:41:25 [base_events/ERROR]: Task was destroyed but it is pending!
task: <Task pending name='Task-7' coro=<Exchange.load_markets_helper() running at /usr/local/lib/python3.10/site-packages/ccxt/async_support/base/exchange.py:190> wait_for=<Future pending cb=[Task.task_wakeup()]> cb=[Task.task_wakeup()]>
2022-09-08 16:41:25 [base_events/ERROR]: Unclosed client session
client_session: <aiohttp.client.ClientSession object at 0x7faa5e085660>
2022-09-08 16:41:25 [base_events/ERROR]: Unclosed connector
connections: ['[(<aiohttp.client_proto.ResponseHandler object at 0x7faa5e080880>, 2368.105788947)]']
connector: <aiohttp.connector.TCPConnector object at 0x7faa5e1bdbd0>
2022-09-08 16:43:25 [base_events/ERROR]: Fatal error on SSL transport
protocol: <asyncio.sslproto.SSLProtocol object at 0x7ff9bfea6110>
transport: <_SelectorSocketTransport closing fd=9>
Traceback (most recent call last):
  File "/usr/local/lib/python3.10/asyncio/selector_events.py", line 916, in write
    n = self._sock.send(data)
OSError: [Errno 9] Bad file descriptor

During handling of the above exception, another exception occurred:

Traceback (most recent call last):
  File "/usr/local/lib/python3.10/asyncio/sslproto.py", line 690, in _process_write_backlog
    self._transport.write(chunk)
  File "/usr/local/lib/python3.10/asyncio/selector_events.py", line 922, in write
    self._fatal_error(exc, 'Fatal write error on socket transport')
  File "/usr/local/lib/python3.10/asyncio/selector_events.py", line 717, in _fatal_error
    self._force_close(exc)
  File "/usr/local/lib/python3.10/asyncio/selector_events.py", line 729, in _force_close
    self._loop.call_soon(self._call_connection_lost, exc)
  File "/usr/local/lib/python3.10/asyncio/base_events.py", line 750, in call_soon
    self._check_closed()
  File "/usr/local/lib/python3.10/asyncio/base_events.py", line 515, in _check_closed
    raise RuntimeError('Event loop is closed')
RuntimeError: Event loop is closed
2022-09-08 16:43:25 [base_events/ERROR]: Task was destroyed but it is pending!
task: <Task pending name='Task-18' coro=<Throttler.looper() running at /usr/local/lib/python3.10/site-packages/ccxt/async_support/base/throttler.py:36> wait_for=<Future pending cb=[Task.task_wakeup()]>>
2022-09-08 16:43:25 [base_events/ERROR]: Task was destroyed but it is pending!
task: <Task pending name='Task-36' coro=<Throttler.looper() running at /usr/local/lib/python3.10/site-packages/ccxt/async_support/base/throttler.py:36> wait_for=<Future pending cb=[Task.task_wakeup()]>>
2022-09-08 16:43:25 [base_events/ERROR]: Fatal error on SSL transport
protocol: <asyncio.sslproto.SSLProtocol object at 0x7ff9bffd97e0>
transport: <_SelectorSocketTransport closing fd=10>
Traceback (most recent call last):
  File "/usr/local/lib/python3.10/asyncio/selector_events.py", line 916, in write
    n = self._sock.send(data)
OSError: [Errno 9] Bad file descriptor

During handling of the above exception, another exception occurred:

Traceback (most recent call last):
  File "/usr/local/lib/python3.10/asyncio/sslproto.py", line 690, in _process_write_backlog
    self._transport.write(chunk)
  File "/usr/local/lib/python3.10/asyncio/selector_events.py", line 922, in write
    self._fatal_error(exc, 'Fatal write error on socket transport')
  File "/usr/local/lib/python3.10/asyncio/selector_events.py", line 717, in _fatal_error
    self._force_close(exc)
  File "/usr/local/lib/python3.10/asyncio/selector_events.py", line 729, in _force_close
    self._loop.call_soon(self._call_connection_lost, exc)
  File "/usr/local/lib/python3.10/asyncio/base_events.py", line 750, in call_soon
    self._check_closed()
  File "/usr/local/lib/python3.10/asyncio/base_events.py", line 515, in _check_closed
    raise RuntimeError('Event loop is closed')
RuntimeError: Event loop is closed
2022-09-08 16:43:25 [base_events/ERROR]: Fatal error on SSL transport
protocol: <asyncio.sslproto.SSLProtocol object at 0x7ff9bfea6590>
transport: <_SelectorSocketTransport closing fd=8>
Traceback (most recent call last):
  File "/usr/local/lib/python3.10/asyncio/selector_events.py", line 916, in write
    n = self._sock.send(data)
OSError: [Errno 9] Bad file descriptor

During handling of the above exception, another exception occurred:

Traceback (most recent call last):
  File "/usr/local/lib/python3.10/asyncio/sslproto.py", line 690, in _process_write_backlog
    self._transport.write(chunk)
  File "/usr/local/lib/python3.10/asyncio/selector_events.py", line 922, in write
    self._fatal_error(exc, 'Fatal write error on socket transport')
  File "/usr/local/lib/python3.10/asyncio/selector_events.py", line 717, in _fatal_error
    self._force_close(exc)
  File "/usr/local/lib/python3.10/asyncio/selector_events.py", line 729, in _force_close
    self._loop.call_soon(self._call_connection_lost, exc)
  File "/usr/local/lib/python3.10/asyncio/base_events.py", line 750, in call_soon
    self._check_closed()
  File "/usr/local/lib/python3.10/asyncio/base_events.py", line 515, in _check_closed
    raise RuntimeError('Event loop is closed')
RuntimeError: Event loop is closed
2022-09-08 16:43:25 [base_events/ERROR]: Unclosed client session
client_session: <aiohttp.client.ClientSession object at 0x7ff9bfea51e0>
2022-09-08 16:43:25 [base_events/ERROR]: Unclosed connector
connections: ['[(<aiohttp.client_proto.ResponseHandler object at 0x7ff9bfea1ae0>, 2490.512533941)]']
connector: <aiohttp.connector.TCPConnector object at 0x7ff9bfe73d60>
2022-09-08 16:43:25 [base_events/ERROR]: Unclosed client session
client_session: <aiohttp.client.ClientSession object at 0x7ff9bfea4e80>
2022-09-08 16:43:25 [base_events/ERROR]: Unclosed connector
connections: ['[(<aiohttp.client_proto.ResponseHandler object at 0x7ff9bfea1540>, 2490.365252656)]']
connector: <aiohttp.connector.TCPConnector object at 0x7ff9bffd95a0>
2022-09-08 16:43:25 [base_events/ERROR]: Task was destroyed but it is pending!
task: <Task pending name='Task-7' coro=<Exchange.load_markets_helper() running at /usr/local/lib/python3.10/site-packages/ccxt/async_support/base/exchange.py:190> wait_for=<Future pending cb=[Task.task_wakeup()]> cb=[Task.task_wakeup()]>
2022-09-08 16:43:25 [base_events/ERROR]: Unclosed client session
client_session: <aiohttp.client.ClientSession object at 0x7ff9bfea55a0>
2022-09-08 16:43:25 [base_events/ERROR]: Unclosed connector
connections: ['[(<aiohttp.client_proto.ResponseHandler object at 0x7ff9bfea17e0>, 2488.504657574)]']
connector: <aiohttp.connector.TCPConnector object at 0x7ff9bffd9b10>
2022-09-08 16:45:12 [base_events/ERROR]: Fatal error on SSL transport
protocol: <asyncio.sslproto.SSLProtocol object at 0x7fe24dd0e170>
transport: <_SelectorSocketTransport closing fd=9>
Traceback (most recent call last):
  File "/usr/local/lib/python3.10/asyncio/selector_events.py", line 916, in write
    n = self._sock.send(data)
OSError: [Errno 9] Bad file descriptor

During handling of the above exception, another exception occurred:

Traceback (most recent call last):
  File "/usr/local/lib/python3.10/asyncio/sslproto.py", line 690, in _process_write_backlog
    self._transport.write(chunk)
  File "/usr/local/lib/python3.10/asyncio/selector_events.py", line 922, in write
    self._fatal_error(exc, 'Fatal write error on socket transport')
  File "/usr/local/lib/python3.10/asyncio/selector_events.py", line 717, in _fatal_error
    self._force_close(exc)
  File "/usr/local/lib/python3.10/asyncio/selector_events.py", line 729, in _force_close
    self._loop.call_soon(self._call_connection_lost, exc)
  File "/usr/local/lib/python3.10/asyncio/base_events.py", line 750, in call_soon
    self._check_closed()
  File "/usr/local/lib/python3.10/asyncio/base_events.py", line 515, in _check_closed
    raise RuntimeError('Event loop is closed')
RuntimeError: Event loop is closed
2022-09-08 16:45:12 [base_events/ERROR]: Task was destroyed but it is pending!
task: <Task pending name='Task-43' coro=<Throttler.looper() running at /usr/local/lib/python3.10/site-packages/ccxt/async_support/base/throttler.py:36> wait_for=<Future pending cb=[Task.task_wakeup()]>>
2022-09-08 16:45:12 [base_events/ERROR]: Fatal error on SSL transport
protocol: <asyncio.sslproto.SSLProtocol object at 0x7fe24dd0d9c0>
transport: <_SelectorSocketTransport closing fd=8>
Traceback (most recent call last):
  File "/usr/local/lib/python3.10/asyncio/selector_events.py", line 916, in write
    n = self._sock.send(data)
OSError: [Errno 9] Bad file descriptor

During handling of the above exception, another exception occurred:

Traceback (most recent call last):
  File "/usr/local/lib/python3.10/asyncio/sslproto.py", line 690, in _process_write_backlog
    self._transport.write(chunk)
  File "/usr/local/lib/python3.10/asyncio/selector_events.py", line 922, in write
    self._fatal_error(exc, 'Fatal write error on socket transport')
  File "/usr/local/lib/python3.10/asyncio/selector_events.py", line 717, in _fatal_error
    self._force_close(exc)
  File "/usr/local/lib/python3.10/asyncio/selector_events.py", line 729, in _force_close
    self._loop.call_soon(self._call_connection_lost, exc)
  File "/usr/local/lib/python3.10/asyncio/base_events.py", line 750, in call_soon
    self._check_closed()
  File "/usr/local/lib/python3.10/asyncio/base_events.py", line 515, in _check_closed
    raise RuntimeError('Event loop is closed')
RuntimeError: Event loop is closed
2022-09-08 16:45:12 [base_events/ERROR]: Fatal error on SSL transport
protocol: <asyncio.sslproto.SSLProtocol object at 0x7fe24dd0e5f0>
transport: <_SelectorSocketTransport closing fd=10>
Traceback (most recent call last):
  File "/usr/local/lib/python3.10/asyncio/selector_events.py", line 916, in write
    n = self._sock.send(data)
OSError: [Errno 9] Bad file descriptor

During handling of the above exception, another exception occurred:

Traceback (most recent call last):
  File "/usr/local/lib/python3.10/asyncio/sslproto.py", line 690, in _process_write_backlog
    self._transport.write(chunk)
  File "/usr/local/lib/python3.10/asyncio/selector_events.py", line 922, in write
    self._fatal_error(exc, 'Fatal write error on socket transport')
  File "/usr/local/lib/python3.10/asyncio/selector_events.py", line 717, in _fatal_error
    self._force_close(exc)
  File "/usr/local/lib/python3.10/asyncio/selector_events.py", line 729, in _force_close
    self._loop.call_soon(self._call_connection_lost, exc)
  File "/usr/local/lib/python3.10/asyncio/base_events.py", line 750, in call_soon
    self._check_closed()
  File "/usr/local/lib/python3.10/asyncio/base_events.py", line 515, in _check_closed
    raise RuntimeError('Event loop is closed')
RuntimeError: Event loop is closed
2022-09-08 16:45:12 [base_events/ERROR]: Unclosed client session
client_session: <aiohttp.client.ClientSession object at 0x7fe24dd0d240>
2022-09-08 16:45:12 [base_events/ERROR]: Unclosed connector
connections: ['[(<aiohttp.client_proto.ResponseHandler object at 0x7fe24dd08a60>, 2597.723267626)]']
connector: <aiohttp.connector.TCPConnector object at 0x7fe24dcdbdc0>
2022-09-08 16:45:12 [base_events/ERROR]: Unclosed client session
client_session: <aiohttp.client.ClientSession object at 0x7fe24dd0cee0>
2022-09-08 16:45:12 [base_events/ERROR]: Unclosed connector
connections: ['[(<aiohttp.client_proto.ResponseHandler object at 0x7fe24dd08880>, 2597.779807896)]']
connector: <aiohttp.connector.TCPConnector object at 0x7fe24de45600>
2022-09-08 16:45:12 [base_events/ERROR]: Unclosed client session
client_session: <aiohttp.client.ClientSession object at 0x7fe24dd0d600>
2022-09-08 16:45:12 [base_events/ERROR]: Unclosed connector
connections: ['[(<aiohttp.client_proto.ResponseHandler object at 0x7fe24dd08b20>, 2597.07876455)]']
connector: <aiohttp.connector.TCPConnector object at 0x7fe24de45b70>
2022-09-08 16:47:16 [base_events/ERROR]: Fatal error on SSL transport
protocol: <asyncio.sslproto.SSLProtocol object at 0x7f450806a1d0>
transport: <_SelectorSocketTransport closing fd=10>
Traceback (most recent call last):
  File "/usr/local/lib/python3.10/asyncio/selector_events.py", line 916, in write
    n = self._sock.send(data)
OSError: [Errno 9] Bad file descriptor

During handling of the above exception, another exception occurred:

Traceback (most recent call last):
  File "/usr/local/lib/python3.10/asyncio/sslproto.py", line 690, in _process_write_backlog
    self._transport.write(chunk)
  File "/usr/local/lib/python3.10/asyncio/selector_events.py", line 922, in write
    self._fatal_error(exc, 'Fatal write error on socket transport')
  File "/usr/local/lib/python3.10/asyncio/selector_events.py", line 717, in _fatal_error
    self._force_close(exc)
  File "/usr/local/lib/python3.10/asyncio/selector_events.py", line 729, in _force_close
    self._loop.call_soon(self._call_connection_lost, exc)
  File "/usr/local/lib/python3.10/asyncio/base_events.py", line 750, in call_soon
    self._check_closed()
  File "/usr/local/lib/python3.10/asyncio/base_events.py", line 515, in _check_closed
    raise RuntimeError('Event loop is closed')
RuntimeError: Event loop is closed
2022-09-08 16:47:16 [base_events/ERROR]: Fatal error on SSL transport
protocol: <asyncio.sslproto.SSLProtocol object at 0x7f4508069a20>
transport: <_SelectorSocketTransport closing fd=8>
Traceback (most recent call last):
  File "/usr/local/lib/python3.10/asyncio/selector_events.py", line 916, in write
    n = self._sock.send(data)
OSError: [Errno 9] Bad file descriptor

During handling of the above exception, another exception occurred:

Traceback (most recent call last):
  File "/usr/local/lib/python3.10/asyncio/sslproto.py", line 690, in _process_write_backlog
    self._transport.write(chunk)
  File "/usr/local/lib/python3.10/asyncio/selector_events.py", line 922, in write
    self._fatal_error(exc, 'Fatal write error on socket transport')
  File "/usr/local/lib/python3.10/asyncio/selector_events.py", line 717, in _fatal_error
    self._force_close(exc)
  File "/usr/local/lib/python3.10/asyncio/selector_events.py", line 729, in _force_close
    self._loop.call_soon(self._call_connection_lost, exc)
  File "/usr/local/lib/python3.10/asyncio/base_events.py", line 750, in call_soon
    self._check_closed()
  File "/usr/local/lib/python3.10/asyncio/base_events.py", line 515, in _check_closed
    raise RuntimeError('Event loop is closed')
RuntimeError: Event loop is closed
2022-09-08 16:47:16 [base_events/ERROR]: Fatal error on SSL transport
protocol: <asyncio.sslproto.SSLProtocol object at 0x7f450806a650>
transport: <_SelectorSocketTransport closing fd=9>
Traceback (most recent call last):
  File "/usr/local/lib/python3.10/asyncio/selector_events.py", line 916, in write
    n = self._sock.send(data)
OSError: [Errno 9] Bad file descriptor

During handling of the above exception, another exception occurred:

Traceback (most recent call last):
  File "/usr/local/lib/python3.10/asyncio/sslproto.py", line 690, in _process_write_backlog
    self._transport.write(chunk)
  File "/usr/local/lib/python3.10/asyncio/selector_events.py", line 922, in write
    self._fatal_error(exc, 'Fatal write error on socket transport')
  File "/usr/local/lib/python3.10/asyncio/selector_events.py", line 717, in _fatal_error
    self._force_close(exc)
  File "/usr/local/lib/python3.10/asyncio/selector_events.py", line 729, in _force_close
    self._loop.call_soon(self._call_connection_lost, exc)
  File "/usr/local/lib/python3.10/asyncio/base_events.py", line 750, in call_soon
    self._check_closed()
  File "/usr/local/lib/python3.10/asyncio/base_events.py", line 515, in _check_closed
    raise RuntimeError('Event loop is closed')
RuntimeError: Event loop is closed
2022-09-08 16:47:16 [base_events/ERROR]: Unclosed client session
client_session: <aiohttp.client.ClientSession object at 0x7f4508068f40>
2022-09-08 16:47:16 [base_events/ERROR]: Unclosed connector
connections: ['[(<aiohttp.client_proto.ResponseHandler object at 0x7f4508064b20>, 2722.470681093)]']
connector: <aiohttp.connector.TCPConnector object at 0x7f45081a1660>
2022-09-08 16:47:16 [base_events/ERROR]: Unclosed client session
client_session: <aiohttp.client.ClientSession object at 0x7f45080692a0>
2022-09-08 16:47:17 [base_events/ERROR]: Task was destroyed but it is pending!
task: <Task pending name='Task-7' coro=<Exchange.load_markets_helper() running at /usr/local/lib/python3.10/site-packages/ccxt/async_support/base/exchange.py:190> wait_for=<Future pending cb=[Task.task_wakeup()]> cb=[Task.task_wakeup()]>
2022-09-08 16:47:17 [base_events/ERROR]: Unclosed client session
client_session: <aiohttp.client.ClientSession object at 0x7f4508069660>
2022-09-08 16:48:03 [base_events/ERROR]: Fatal error on SSL transport
protocol: <asyncio.sslproto.SSLProtocol object at 0x7fd0d52f2950>
transport: <_SelectorSocketTransport closing fd=10>
Traceback (most recent call last):
  File "/usr/local/lib/python3.10/asyncio/selector_events.py", line 916, in write
    n = self._sock.send(data)
OSError: [Errno 9] Bad file descriptor

During handling of the above exception, another exception occurred:

Traceback (most recent call last):
  File "/usr/local/lib/python3.10/asyncio/sslproto.py", line 690, in _process_write_backlog
    self._transport.write(chunk)
  File "/usr/local/lib/python3.10/asyncio/selector_events.py", line 922, in write
    self._fatal_error(exc, 'Fatal write error on socket transport')
  File "/usr/local/lib/python3.10/asyncio/selector_events.py", line 717, in _fatal_error
    self._force_close(exc)
  File "/usr/local/lib/python3.10/asyncio/selector_events.py", line 729, in _force_close
    self._loop.call_soon(self._call_connection_lost, exc)
  File "/usr/local/lib/python3.10/asyncio/base_events.py", line 750, in call_soon
    self._check_closed()
  File "/usr/local/lib/python3.10/asyncio/base_events.py", line 515, in _check_closed
    raise RuntimeError('Event loop is closed')
RuntimeError: Event loop is closed
2022-09-08 16:48:03 [base_events/ERROR]: Fatal error on SSL transport
protocol: <asyncio.sslproto.SSLProtocol object at 0x7fd0d52f2170>
transport: <_SelectorSocketTransport closing fd=9>
Traceback (most recent call last):
  File "/usr/local/lib/python3.10/asyncio/selector_events.py", line 916, in write
    n = self._sock.send(data)
OSError: [Errno 9] Bad file descriptor

During handling of the above exception, another exception occurred:

Traceback (most recent call last):
  File "/usr/local/lib/python3.10/asyncio/sslproto.py", line 690, in _process_write_backlog
    self._transport.write(chunk)
  File "/usr/local/lib/python3.10/asyncio/selector_events.py", line 922, in write
    self._fatal_error(exc, 'Fatal write error on socket transport')
  File "/usr/local/lib/python3.10/asyncio/selector_events.py", line 717, in _fatal_error
    self._force_close(exc)
  File "/usr/local/lib/python3.10/asyncio/selector_events.py", line 729, in _force_close
    self._loop.call_soon(self._call_connection_lost, exc)
  File "/usr/local/lib/python3.10/asyncio/base_events.py", line 750, in call_soon
    self._check_closed()
  File "/usr/local/lib/python3.10/asyncio/base_events.py", line 515, in _check_closed
    raise RuntimeError('Event loop is closed')
RuntimeError: Event loop is closed
2022-09-08 16:48:03 [base_events/ERROR]: Task was destroyed but it is pending!
task: <Task pending name='Task-17' coro=<Throttler.looper() running at /usr/local/lib/python3.10/site-packages/ccxt/async_support/base/throttler.py:36> wait_for=<Future pending cb=[Task.task_wakeup()]>>
2022-09-08 16:48:03 [base_events/ERROR]: Task was destroyed but it is pending!
task: <Task pending name='Task-30' coro=<Throttler.looper() running at /usr/local/lib/python3.10/site-packages/ccxt/async_support/base/throttler.py:36> wait_for=<Future pending cb=[Task.task_wakeup()]>>
2022-09-08 16:48:03 [base_events/ERROR]: Fatal error on SSL transport
protocol: <asyncio.sslproto.SSLProtocol object at 0x7fd0d52f25f0>
transport: <_SelectorSocketTransport closing fd=8>
Traceback (most recent call last):
  File "/usr/local/lib/python3.10/asyncio/selector_events.py", line 916, in write
    n = self._sock.send(data)
OSError: [Errno 9] Bad file descriptor

During handling of the above exception, another exception occurred:

Traceback (most recent call last):
  File "/usr/local/lib/python3.10/asyncio/sslproto.py", line 690, in _process_write_backlog
    self._transport.write(chunk)
  File "/usr/local/lib/python3.10/asyncio/selector_events.py", line 922, in write
    self._fatal_error(exc, 'Fatal write error on socket transport')
  File "/usr/local/lib/python3.10/asyncio/selector_events.py", line 717, in _fatal_error
    self._force_close(exc)
  File "/usr/local/lib/python3.10/asyncio/selector_events.py", line 729, in _force_close
    self._loop.call_soon(self._call_connection_lost, exc)
  File "/usr/local/lib/python3.10/asyncio/base_events.py", line 750, in call_soon
    self._check_closed()
  File "/usr/local/lib/python3.10/asyncio/base_events.py", line 515, in _check_closed
    raise RuntimeError('Event loop is closed')
RuntimeError: Event loop is closed
2022-09-08 16:48:03 [base_events/ERROR]: Unclosed client session
client_session: <aiohttp.client.ClientSession object at 0x7fd0d52f1240>
2022-09-08 16:48:03 [base_events/ERROR]: Unclosed connector
connections: ['[(<aiohttp.client_proto.ResponseHandler object at 0x7fd0d52eca60>, 2768.627127652)]']
connector: <aiohttp.connector.TCPConnector object at 0x7fd0d52bfdc0>
2022-09-08 16:48:03 [base_events/ERROR]: Unclosed client session
client_session: <aiohttp.client.ClientSession object at 0x7fd0d52f0ee0>
2022-09-08 16:48:03 [base_events/ERROR]: Unclosed connector
connections: ['[(<aiohttp.client_proto.ResponseHandler object at 0x7fd0d52ecb20>, 2768.569688821)]']
connector: <aiohttp.connector.TCPConnector object at 0x7fd0d5425600>
2022-09-08 16:48:03 [base_events/ERROR]: Task was destroyed but it is pending!
task: <Task pending name='Task-7' coro=<Exchange.load_markets_helper() running at /usr/local/lib/python3.10/site-packages/ccxt/async_support/base/exchange.py:190> wait_for=<Future pending cb=[Task.task_wakeup()]> cb=[Task.task_wakeup()]>
2022-09-08 16:48:03 [base_events/ERROR]: Unclosed client session
client_session: <aiohttp.client.ClientSession object at 0x7fd0d52f1600>
2022-09-08 16:48:03 [base_events/ERROR]: Unclosed connector
connections: ['[(<aiohttp.client_proto.ResponseHandler object at 0x7fd0d52ed480>, 2766.97046413)]']
connector: <aiohttp.connector.TCPConnector object at 0x7fd0d5425b70>
2022-09-08 16:53:17 [base_events/ERROR]: Fatal error on SSL transport
protocol: <asyncio.sslproto.SSLProtocol object at 0x7f2625dbd0c0>
transport: <_SelectorSocketTransport closing fd=9>
Traceback (most recent call last):
  File "/usr/local/lib/python3.10/asyncio/selector_events.py", line 916, in write
    n = self._sock.send(data)
OSError: [Errno 9] Bad file descriptor

During handling of the above exception, another exception occurred:

Traceback (most recent call last):
  File "/usr/local/lib/python3.10/asyncio/sslproto.py", line 690, in _process_write_backlog
    self._transport.write(chunk)
  File "/usr/local/lib/python3.10/asyncio/selector_events.py", line 922, in write
    self._fatal_error(exc, 'Fatal write error on socket transport')
  File "/usr/local/lib/python3.10/asyncio/selector_events.py", line 717, in _fatal_error
    self._force_close(exc)
  File "/usr/local/lib/python3.10/asyncio/selector_events.py", line 729, in _force_close
    self._loop.call_soon(self._call_connection_lost, exc)
  File "/usr/local/lib/python3.10/asyncio/base_events.py", line 750, in call_soon
    self._check_closed()
  File "/usr/local/lib/python3.10/asyncio/base_events.py", line 515, in _check_closed
    raise RuntimeError('Event loop is closed')
RuntimeError: Event loop is closed
2022-09-08 16:53:17 [base_events/ERROR]: Task was destroyed but it is pending!
task: <Task pending name='Task-18' coro=<Throttler.looper() running at /usr/local/lib/python3.10/site-packages/ccxt/async_support/base/throttler.py:36> wait_for=<Future pending cb=[Task.task_wakeup()]>>
2022-09-08 16:53:17 [base_events/ERROR]: Task was destroyed but it is pending!
task: <Task pending name='Task-28' coro=<Throttler.looper() running at /usr/local/lib/python3.10/site-packages/ccxt/async_support/base/throttler.py:36> wait_for=<Future pending cb=[Task.task_wakeup()]>>
2022-09-08 16:53:17 [base_events/ERROR]: Task was destroyed but it is pending!
task: <Task pending name='Task-29' coro=<Throttler.looper() running at /usr/local/lib/python3.10/site-packages/ccxt/async_support/base/throttler.py:36> wait_for=<Future pending cb=[Task.task_wakeup()]>>
2022-09-08 16:53:17 [base_events/ERROR]: Fatal error on SSL transport
protocol: <asyncio.sslproto.SSLProtocol object at 0x7f2625dbcc70>
transport: <_SelectorSocketTransport closing fd=8>
Traceback (most recent call last):
  File "/usr/local/lib/python3.10/asyncio/selector_events.py", line 916, in write
    n = self._sock.send(data)
OSError: [Errno 9] Bad file descriptor

During handling of the above exception, another exception occurred:

Traceback (most recent call last):
  File "/usr/local/lib/python3.10/asyncio/sslproto.py", line 690, in _process_write_backlog
    self._transport.write(chunk)
  File "/usr/local/lib/python3.10/asyncio/selector_events.py", line 922, in write
    self._fatal_error(exc, 'Fatal write error on socket transport')
  File "/usr/local/lib/python3.10/asyncio/selector_events.py", line 717, in _fatal_error
    self._force_close(exc)
  File "/usr/local/lib/python3.10/asyncio/selector_events.py", line 729, in _force_close
    self._loop.call_soon(self._call_connection_lost, exc)
  File "/usr/local/lib/python3.10/asyncio/base_events.py", line 750, in call_soon
    self._check_closed()
  File "/usr/local/lib/python3.10/asyncio/base_events.py", line 515, in _check_closed
    raise RuntimeError('Event loop is closed')
RuntimeError: Event loop is closed
2022-09-08 16:53:17 [base_events/ERROR]: Fatal error on SSL transport
protocol: <asyncio.sslproto.SSLProtocol object at 0x7f2625dbd3f0>
transport: <_SelectorSocketTransport closing fd=10>
Traceback (most recent call last):
  File "/usr/local/lib/python3.10/asyncio/selector_events.py", line 916, in write
    n = self._sock.send(data)
OSError: [Errno 9] Bad file descriptor

During handling of the above exception, another exception occurred:

Traceback (most recent call last):
  File "/usr/local/lib/python3.10/asyncio/sslproto.py", line 690, in _process_write_backlog
    self._transport.write(chunk)
  File "/usr/local/lib/python3.10/asyncio/selector_events.py", line 922, in write
    self._fatal_error(exc, 'Fatal write error on socket transport')
  File "/usr/local/lib/python3.10/asyncio/selector_events.py", line 717, in _fatal_error
    self._force_close(exc)
  File "/usr/local/lib/python3.10/asyncio/selector_events.py", line 729, in _force_close
    self._loop.call_soon(self._call_connection_lost, exc)
  File "/usr/local/lib/python3.10/asyncio/base_events.py", line 750, in call_soon
    self._check_closed()
  File "/usr/local/lib/python3.10/asyncio/base_events.py", line 515, in _check_closed
    raise RuntimeError('Event loop is closed')
RuntimeError: Event loop is closed
2022-09-08 16:53:17 [base_events/ERROR]: Unclosed client session
client_session: <aiohttp.client.ClientSession object at 0x7f2625d794e0>
2022-09-08 16:53:17 [base_events/ERROR]: Unclosed connector
connections: ['[(<aiohttp.client_proto.ResponseHandler object at 0x7f2625d80580>, 3083.087958316)]']
connector: <aiohttp.connector.TCPConnector object at 0x7f2625eadae0>
2022-09-08 16:53:17 [base_events/ERROR]: Unclosed client session
client_session: <aiohttp.client.ClientSession object at 0x7f2625d79180>
2022-09-08 16:53:17 [base_events/ERROR]: Unclosed connector
connections: ['[(<aiohttp.client_proto.ResponseHandler object at 0x7f2625d80820>, 3082.957439884)]']
connector: <aiohttp.connector.TCPConnector object at 0x7f2625ead570>
2022-09-08 16:53:17 [base_events/ERROR]: Task was destroyed but it is pending!
task: <Task pending name='Task-7' coro=<Exchange.load_markets_helper() running at /usr/local/lib/python3.10/site-packages/ccxt/async_support/base/exchange.py:190> wait_for=<Future pending cb=[Task.task_wakeup()]> cb=[Task.task_wakeup()]>
2022-09-08 16:53:17 [base_events/ERROR]: Unclosed client session
client_session: <aiohttp.client.ClientSession object at 0x7f2625d798a0>
2022-09-08 16:53:17 [base_events/ERROR]: Unclosed connector
connections: ['[(<aiohttp.client_proto.ResponseHandler object at 0x7f2625d81540>, 3081.69289668)]']
connector: <aiohttp.connector.TCPConnector object at 0x7f2625eade10>
2022-09-08 16:53:51 [base_events/ERROR]: Fatal error on SSL transport
protocol: <asyncio.sslproto.SSLProtocol object at 0x7f4c3e5eed70>
transport: <_SelectorSocketTransport closing fd=10>
Traceback (most recent call last):
  File "/usr/local/lib/python3.10/asyncio/selector_events.py", line 916, in write
    n = self._sock.send(data)
OSError: [Errno 9] Bad file descriptor

During handling of the above exception, another exception occurred:

Traceback (most recent call last):
  File "/usr/local/lib/python3.10/asyncio/sslproto.py", line 690, in _process_write_backlog
    self._transport.write(chunk)
  File "/usr/local/lib/python3.10/asyncio/selector_events.py", line 922, in write
    self._fatal_error(exc, 'Fatal write error on socket transport')
  File "/usr/local/lib/python3.10/asyncio/selector_events.py", line 717, in _fatal_error
    self._force_close(exc)
  File "/usr/local/lib/python3.10/asyncio/selector_events.py", line 729, in _force_close
    self._loop.call_soon(self._call_connection_lost, exc)
  File "/usr/local/lib/python3.10/asyncio/base_events.py", line 750, in call_soon
    self._check_closed()
  File "/usr/local/lib/python3.10/asyncio/base_events.py", line 515, in _check_closed
    raise RuntimeError('Event loop is closed')
RuntimeError: Event loop is closed
2022-09-08 16:53:51 [base_events/ERROR]: Fatal error on SSL transport
protocol: <asyncio.sslproto.SSLProtocol object at 0x7f4c3e5ee8c0>
transport: <_SelectorSocketTransport closing fd=8>
Traceback (most recent call last):
  File "/usr/local/lib/python3.10/asyncio/selector_events.py", line 916, in write
    n = self._sock.send(data)
OSError: [Errno 9] Bad file descriptor

During handling of the above exception, another exception occurred:

Traceback (most recent call last):
  File "/usr/local/lib/python3.10/asyncio/sslproto.py", line 690, in _process_write_backlog
    self._transport.write(chunk)
  File "/usr/local/lib/python3.10/asyncio/selector_events.py", line 922, in write
    self._fatal_error(exc, 'Fatal write error on socket transport')
  File "/usr/local/lib/python3.10/asyncio/selector_events.py", line 717, in _fatal_error
    self._force_close(exc)
  File "/usr/local/lib/python3.10/asyncio/selector_events.py", line 729, in _force_close
    self._loop.call_soon(self._call_connection_lost, exc)
  File "/usr/local/lib/python3.10/asyncio/base_events.py", line 750, in call_soon
    self._check_closed()
  File "/usr/local/lib/python3.10/asyncio/base_events.py", line 515, in _check_closed
    raise RuntimeError('Event loop is closed')
RuntimeError: Event loop is closed
2022-09-08 16:53:51 [base_events/ERROR]: Task was destroyed but it is pending!
task: <Task pending name='Task-19' coro=<Throttler.looper() running at /usr/local/lib/python3.10/site-packages/ccxt/async_support/base/throttler.py:36> wait_for=<Future pending cb=[Task.task_wakeup()]>>
2022-09-08 16:53:51 [base_events/ERROR]: Fatal error on SSL transport
protocol: <asyncio.sslproto.SSLProtocol object at 0x7f4c3e5eea10>
transport: <_SelectorSocketTransport closing fd=9>
Traceback (most recent call last):
  File "/usr/local/lib/python3.10/asyncio/selector_events.py", line 916, in write
    n = self._sock.send(data)
OSError: [Errno 9] Bad file descriptor

During handling of the above exception, another exception occurred:

Traceback (most recent call last):
  File "/usr/local/lib/python3.10/asyncio/sslproto.py", line 690, in _process_write_backlog
    self._transport.write(chunk)
  File "/usr/local/lib/python3.10/asyncio/selector_events.py", line 922, in write
    self._fatal_error(exc, 'Fatal write error on socket transport')
  File "/usr/local/lib/python3.10/asyncio/selector_events.py", line 717, in _fatal_error
    self._force_close(exc)
  File "/usr/local/lib/python3.10/asyncio/selector_events.py", line 729, in _force_close
    self._loop.call_soon(self._call_connection_lost, exc)
  File "/usr/local/lib/python3.10/asyncio/base_events.py", line 750, in call_soon
    self._check_closed()
  File "/usr/local/lib/python3.10/asyncio/base_events.py", line 515, in _check_closed
    raise RuntimeError('Event loop is closed')
RuntimeError: Event loop is closed
2022-09-08 16:53:51 [base_events/ERROR]: Unclosed client session
client_session: <aiohttp.client.ClientSession object at 0x7f4c3e5edb70>
2022-09-08 16:53:51 [base_events/ERROR]: Unclosed connector
connections: ['[(<aiohttp.client_proto.ResponseHandler object at 0x7f4c3e5f9540>, 3116.983793447)]']
connector: <aiohttp.connector.TCPConnector object at 0x7f4c3ef2dc30>
2022-09-08 16:53:51 [base_events/ERROR]: Unclosed client session
client_session: <aiohttp.client.ClientSession object at 0x7f4c3e5ed810>
2022-09-08 16:53:51 [base_events/ERROR]: Task was destroyed but it is pending!
task: <Task pending name='Task-9' coro=<Exchange.load_markets_helper() running at /usr/local/lib/python3.10/site-packages/ccxt/async_support/base/exchange.py:190> wait_for=<Future pending cb=[Task.task_wakeup()]> cb=[Task.task_wakeup()]>
2022-09-08 16:53:51 [base_events/ERROR]: Unclosed client session
client_session: <aiohttp.client.ClientSession object at 0x7f4c3e5edf30>
2022-09-08 16:53:51 [base_events/ERROR]: Unclosed connector
connections: ['[(<aiohttp.client_proto.ResponseHandler object at 0x7f4c3e5f9c60>, 3114.97811206)]']
connector: <aiohttp.connector.TCPConnector object at 0x7f4c3ef2d630>
2022-09-08 16:56:12 [base_events/ERROR]: Task was destroyed but it is pending!
task: <Task pending name='Task-30' coro=<Throttler.looper() running at /usr/local/lib/python3.10/site-packages/ccxt/async_support/base/throttler.py:36> wait_for=<Future finished result=None>>
2022-09-08 16:56:12 [base_events/ERROR]: Fatal error on SSL transport
protocol: <asyncio.sslproto.SSLProtocol object at 0x7f64d07f2d40>
transport: <_SelectorSocketTransport closing fd=10>
Traceback (most recent call last):
  File "/usr/local/lib/python3.10/asyncio/selector_events.py", line 916, in write
    n = self._sock.send(data)
OSError: [Errno 9] Bad file descriptor

During handling of the above exception, another exception occurred:

Traceback (most recent call last):
  File "/usr/local/lib/python3.10/asyncio/sslproto.py", line 690, in _process_write_backlog
    self._transport.write(chunk)
  File "/usr/local/lib/python3.10/asyncio/selector_events.py", line 922, in write
    self._fatal_error(exc, 'Fatal write error on socket transport')
  File "/usr/local/lib/python3.10/asyncio/selector_events.py", line 717, in _fatal_error
    self._force_close(exc)
  File "/usr/local/lib/python3.10/asyncio/selector_events.py", line 729, in _force_close
    self._loop.call_soon(self._call_connection_lost, exc)
  File "/usr/local/lib/python3.10/asyncio/base_events.py", line 750, in call_soon
    self._check_closed()
  File "/usr/local/lib/python3.10/asyncio/base_events.py", line 515, in _check_closed
    raise RuntimeError('Event loop is closed')
RuntimeError: Event loop is closed
2022-09-08 16:56:12 [base_events/ERROR]: Fatal error on SSL transport
protocol: <asyncio.sslproto.SSLProtocol object at 0x7f64d07f28c0>
transport: <_SelectorSocketTransport closing fd=9>
Traceback (most recent call last):
  File "/usr/local/lib/python3.10/asyncio/selector_events.py", line 916, in write
    n = self._sock.send(data)
OSError: [Errno 9] Bad file descriptor

During handling of the above exception, another exception occurred:

Traceback (most recent call last):
  File "/usr/local/lib/python3.10/asyncio/sslproto.py", line 690, in _process_write_backlog
    self._transport.write(chunk)
  File "/usr/local/lib/python3.10/asyncio/selector_events.py", line 922, in write
    self._fatal_error(exc, 'Fatal write error on socket transport')
  File "/usr/local/lib/python3.10/asyncio/selector_events.py", line 717, in _fatal_error
    self._force_close(exc)
  File "/usr/local/lib/python3.10/asyncio/selector_events.py", line 729, in _force_close
    self._loop.call_soon(self._call_connection_lost, exc)
  File "/usr/local/lib/python3.10/asyncio/base_events.py", line 750, in call_soon
    self._check_closed()
  File "/usr/local/lib/python3.10/asyncio/base_events.py", line 515, in _check_closed
    raise RuntimeError('Event loop is closed')
RuntimeError: Event loop is closed
2022-09-08 16:56:12 [base_events/ERROR]: Fatal error on SSL transport
protocol: <asyncio.sslproto.SSLProtocol object at 0x7f64d07f2650>
transport: <_SelectorSocketTransport closing fd=8>
Traceback (most recent call last):
  File "/usr/local/lib/python3.10/asyncio/selector_events.py", line 916, in write
    n = self._sock.send(data)
OSError: [Errno 9] Bad file descriptor

During handling of the above exception, another exception occurred:

Traceback (most recent call last):
  File "/usr/local/lib/python3.10/asyncio/sslproto.py", line 690, in _process_write_backlog
    self._transport.write(chunk)
  File "/usr/local/lib/python3.10/asyncio/selector_events.py", line 922, in write
    self._fatal_error(exc, 'Fatal write error on socket transport')
  File "/usr/local/lib/python3.10/asyncio/selector_events.py", line 717, in _fatal_error
    self._force_close(exc)
  File "/usr/local/lib/python3.10/asyncio/selector_events.py", line 729, in _force_close
    self._loop.call_soon(self._call_connection_lost, exc)
  File "/usr/local/lib/python3.10/asyncio/base_events.py", line 750, in call_soon
    self._check_closed()
  File "/usr/local/lib/python3.10/asyncio/base_events.py", line 515, in _check_closed
    raise RuntimeError('Event loop is closed')
RuntimeError: Event loop is closed
2022-09-08 16:56:12 [base_events/ERROR]: Unclosed client session
client_session: <aiohttp.client.ClientSession object at 0x7f64d07f1b70>
2022-09-08 16:56:12 [base_events/ERROR]: Unclosed connector
connections: ['[(<aiohttp.client_proto.ResponseHandler object at 0x7f64d07fd1e0>, 3258.437193379)]']
connector: <aiohttp.connector.TCPConnector object at 0x7f64d11840d0>
2022-09-08 16:56:12 [base_events/ERROR]: Task exception was never retrieved
future: <Task finished name='Task-19' coro=<Throttler.looper() done, defined at /usr/local/lib/python3.10/site-packages/ccxt/async_support/base/throttler.py:21> exception=KeyboardInterrupt()>
Traceback (most recent call last):
  File "/app/bin/main.py", line 64, in <module>
    loop.run_until_complete(run(loop))
  File "/usr/local/lib/python3.10/asyncio/base_events.py", line 633, in run_until_complete
    self.run_forever()
  File "/usr/local/lib/python3.10/asyncio/base_events.py", line 600, in run_forever
    self._run_once()
  File "/usr/local/lib/python3.10/asyncio/base_events.py", line 1896, in _run_once
    handle._run()
  File "/usr/local/lib/python3.10/asyncio/events.py", line 80, in _run
    self._context.run(self._callback, *self._args)
  File "/usr/local/lib/python3.10/site-packages/ccxt/async_support/base/throttler.py", line 36, in looper
    await asyncio.sleep(self.config['delay'])
  File "/usr/local/lib/python3.10/asyncio/tasks.py", line 593, in sleep
    async def sleep(delay, result=None):
KeyboardInterrupt
2022-09-08 16:56:12 [base_events/ERROR]: Unclosed client session
client_session: <aiohttp.client.ClientSession object at 0x7f64d07f1ed0>
2022-09-08 16:56:12 [base_events/ERROR]: Unclosed connector
connections: ['[(<aiohttp.client_proto.ResponseHandler object at 0x7f64d07fd960>, 3258.365089032)]']
connector: <aiohttp.connector.TCPConnector object at 0x7f64d1184dc0>
2022-09-08 16:56:12 [base_events/ERROR]: Task was destroyed but it is pending!
task: <Task pending name='Task-9' coro=<Exchange.load_markets_helper() running at /usr/local/lib/python3.10/site-packages/ccxt/async_support/base/exchange.py:190> wait_for=<Future pending cb=[Task.task_wakeup()]> cb=[Task.task_wakeup()]>
2022-09-08 16:56:12 [base_events/ERROR]: Unclosed client session
client_session: <aiohttp.client.ClientSession object at 0x7f64d07f2290>
2022-09-08 16:56:12 [base_events/ERROR]: Unclosed connector
connections: ['[(<aiohttp.client_proto.ResponseHandler object at 0x7f64d07fd780>, 3256.84264251)]']
connector: <aiohttp.connector.TCPConnector object at 0x7f64d1184df0>
2022-09-08 17:25:56 [base_events/ERROR]: Fatal error on SSL transport
protocol: <asyncio.sslproto.SSLProtocol object at 0x7f8daf096b00>
transport: <_SelectorSocketTransport closing fd=10>
Traceback (most recent call last):
  File "/usr/local/lib/python3.10/asyncio/selector_events.py", line 916, in write
    n = self._sock.send(data)
OSError: [Errno 9] Bad file descriptor

During handling of the above exception, another exception occurred:

Traceback (most recent call last):
  File "/usr/local/lib/python3.10/asyncio/sslproto.py", line 690, in _process_write_backlog
    self._transport.write(chunk)
  File "/usr/local/lib/python3.10/asyncio/selector_events.py", line 922, in write
    self._fatal_error(exc, 'Fatal write error on socket transport')
  File "/usr/local/lib/python3.10/asyncio/selector_events.py", line 717, in _fatal_error
    self._force_close(exc)
  File "/usr/local/lib/python3.10/asyncio/selector_events.py", line 729, in _force_close
    self._loop.call_soon(self._call_connection_lost, exc)
  File "/usr/local/lib/python3.10/asyncio/base_events.py", line 750, in call_soon
    self._check_closed()
  File "/usr/local/lib/python3.10/asyncio/base_events.py", line 515, in _check_closed
    raise RuntimeError('Event loop is closed')
RuntimeError: Event loop is closed
2022-09-08 17:25:56 [base_events/ERROR]: Task was destroyed but it is pending!
task: <Task pending name='Task-20' coro=<Throttler.looper() running at /usr/local/lib/python3.10/site-packages/ccxt/async_support/base/throttler.py:36> wait_for=<Future pending cb=[Task.task_wakeup()]>>
2022-09-08 17:25:56 [base_events/ERROR]: Fatal error on SSL transport
protocol: <asyncio.sslproto.SSLProtocol object at 0x7f8daf096650>
transport: <_SelectorSocketTransport closing fd=8>
Traceback (most recent call last):
  File "/usr/local/lib/python3.10/asyncio/selector_events.py", line 916, in write
    n = self._sock.send(data)
OSError: [Errno 9] Bad file descriptor

During handling of the above exception, another exception occurred:

Traceback (most recent call last):
  File "/usr/local/lib/python3.10/asyncio/sslproto.py", line 690, in _process_write_backlog
    self._transport.write(chunk)
  File "/usr/local/lib/python3.10/asyncio/selector_events.py", line 922, in write
    self._fatal_error(exc, 'Fatal write error on socket transport')
  File "/usr/local/lib/python3.10/asyncio/selector_events.py", line 717, in _fatal_error
    self._force_close(exc)
  File "/usr/local/lib/python3.10/asyncio/selector_events.py", line 729, in _force_close
    self._loop.call_soon(self._call_connection_lost, exc)
  File "/usr/local/lib/python3.10/asyncio/base_events.py", line 750, in call_soon
    self._check_closed()
  File "/usr/local/lib/python3.10/asyncio/base_events.py", line 515, in _check_closed
    raise RuntimeError('Event loop is closed')
RuntimeError: Event loop is closed
2022-09-08 17:25:56 [base_events/ERROR]: Fatal error on SSL transport
protocol: <asyncio.sslproto.SSLProtocol object at 0x7f8daf0967a0>
transport: <_SelectorSocketTransport closing fd=9>
Traceback (most recent call last):
  File "/usr/local/lib/python3.10/asyncio/selector_events.py", line 916, in write
    n = self._sock.send(data)
OSError: [Errno 9] Bad file descriptor

During handling of the above exception, another exception occurred:

Traceback (most recent call last):
  File "/usr/local/lib/python3.10/asyncio/sslproto.py", line 690, in _process_write_backlog
    self._transport.write(chunk)
  File "/usr/local/lib/python3.10/asyncio/selector_events.py", line 922, in write
    self._fatal_error(exc, 'Fatal write error on socket transport')
  File "/usr/local/lib/python3.10/asyncio/selector_events.py", line 717, in _fatal_error
    self._force_close(exc)
  File "/usr/local/lib/python3.10/asyncio/selector_events.py", line 729, in _force_close
    self._loop.call_soon(self._call_connection_lost, exc)
  File "/usr/local/lib/python3.10/asyncio/base_events.py", line 750, in call_soon
    self._check_closed()
  File "/usr/local/lib/python3.10/asyncio/base_events.py", line 515, in _check_closed
    raise RuntimeError('Event loop is closed')
RuntimeError: Event loop is closed
2022-09-08 17:25:56 [base_events/ERROR]: Unclosed client session
client_session: <aiohttp.client.ClientSession object at 0x7f8daf095db0>
2022-09-08 17:25:56 [base_events/ERROR]: Unclosed connector
connections: ['[(<aiohttp.client_proto.ResponseHandler object at 0x7f8daf0a1480>, 5043.639977177)]']
connector: <aiohttp.connector.TCPConnector object at 0x7f8dafa28ca0>
2022-09-08 17:25:56 [base_events/ERROR]: Unclosed client session
client_session: <aiohttp.client.ClientSession object at 0x7f8daf095a50>
2022-09-08 17:25:56 [base_events/ERROR]: Task was destroyed but it is pending!
task: <Task pending name='Task-9' coro=<Exchange.load_markets_helper() running at /usr/local/lib/python3.10/site-packages/ccxt/async_support/base/exchange.py:190> wait_for=<Future pending cb=[Task.task_wakeup()]> cb=[Task.task_wakeup()]>
2022-09-08 17:25:56 [base_events/ERROR]: Unclosed client session
client_session: <aiohttp.client.ClientSession object at 0x7f8daf096170>
2022-09-08 17:25:56 [base_events/ERROR]: Unclosed connector
connections: ['[(<aiohttp.client_proto.ResponseHandler object at 0x7f8daf0a1780>, 5041.854134626)]']
connector: <aiohttp.connector.TCPConnector object at 0x7f8dafa28cd0>
